Workbook

Sheet 출금_피벗
B1: 출금
A3: account type | B3: (모두)
A4: Date | B4: 2021-11-23
A5: ownership | B5: (모두)
A7: 합계 : quantity | B7: 열 레이블
B8: 미확인 | C8: 미확인 요약 | D8: Peertec | E8: Peertec 요약 | F8: 총합계
A9: 행 레이블 | B9: Coinone | D9: FTX
A10: ETH | D10: 563.013 | E10: 563.013 | F10: 563.013
A11: 44523.542 | D11: 563.013 | E11: 563.013 | F11: 563.013
A12: Binance | D12: 563.013 | E12: 563.013 | F12: 563.013
A13: Main | D13: 563.013 | E13: 563.013 | F13: 563.013
A14: XRP | B14: 45293.5 | C14: 45293.5 | F14: 45293.5
A15: 44523.941 | B15: 22576.75 | C15: 22576.75 | F15: 22576.75
A16: Binance | B16: 22576.75 | C16: 22576.75 | F16: 22576.75
A17: Main | B17: 22576.75 | C17: 22576.75 | F17: 22576.75
A18: 44523.884 | B18: 22716.75 | C18: 22716.75 | F18: 22716.75
A19: Binance | B19: 22716.75 | C19: 22716.75 | F19: 22716.75
A20: Main | B20: 22716.75 | C20: 22716.75 | F20: 22716.75
A21: 총합계 | B21: 45293.5 | C21: 45293.5 | D21: 563.013 | E21: 563.013 | F21: 45856.513

Sheet 입금_피벗
B1: 입금
A2: ownership | B2: (모두)
A3: account type | B3: (모두)
A4: Date | B4: 2022-03-18
A5: Deposit_coin | B5: (다중 항목)
A7: 행 레이블 | B7: 합계 : quantity
A8: 44638.428 | B8: 3.254097
A9: FTX | B9: 3.254097
A10: Main_Peertec | B10: 3.254097
A11: 44638.512 | B11: 77.7
A12: Binance | B12: 77.7
A13: Main | B13: 77.7
A14: 총합계 | B14: 80.954097

Sheet 지갑
A1: idx | B1: account type | C1: name | D1: ownership | E1: subname | F1: api id | G1: coin | H1: address | I1: tag | J1: Prefix
A2: 1 | B2: exchange | C2: FTX | D2: Peertec | E2: ='(참고) Index'!$E$2 -> Main_Peertec | F2: 10003 | G2: BTC | H2: 337ne45ueXx2iAR1gNAqxnwsCGuLquCLnh | J2: =H2&I2 -> 337ne45ueXx2iAR1gNAqxnwsCGuLquCLnh | K2: =B2&C2&D2&E2&F2&G2&I2 -> exchangeFTXPeertecMain_Peertec10003BTC
A3: 1 | B3: exchange | C3: FTX | D3: Peertec | E3: ='(참고) Index'!$E$2 -> Main_Peertec | F3: 10003 | G3: XRP | H3: rPFXvVo2fYXVPdV9gCHQouHsMgMhQ2aUwM | I3: 3680179910 | J3: =H3&I3 -> rPFXvVo2fYXVPdV9gCHQouHsMgMhQ2aUwM3680179910 | K3: =B3&C3&D3&E3&F3&G3&I3 -> exchangeFTXPeertecMain_Peertec10003XRP3680179910
A4: 1 | B4: exchange | C4: FTX | D4: Peertec | E4: ='(참고) Index'!$E$2 -> Main_Peertec | F4: 10003 | G4: ETH | H4: 0xaB4Bfe506a3Cb36ADDf97678293bD429B9951726 | J4: =H4&I4 -> 0xaB4Bfe506a3Cb36ADDf97678293bD429B9951726 | K4: =B4&C4&D4&E4&F4&G4&I4 -> exchangeFTXPeertecMain_Peertec10003ETH
A5: 1 | B5: exchange | C5: FTX | D5: Peertec | E5: ='(참고) Index'!$E$2 -> Main_Peertec | F5: 10003 | G5: USDC | H5: 0x8E59558B73A92572834169Dc0096df9E42168B57 | J5: =H5&I5 -> 0x8E59558B73A92572834169Dc0096df9E42168B57 | K5: =B5&C5&D5&E5&F5&G5&I5 -> exchangeFTXPeertecMain_Peertec10003USDC
A6: 1 | B6: exchange | C6: FTX | D6: Peertec | E6: ='(참고) Index'!$E$2 -> Main_Peertec | F6: 10003 | G6: USDT | H6: 0x8f27fa136ff4da1796368380019029d81d12d06d | J6: =H6&I6 -> 0x8f27fa136ff4da1796368380019029d81d12d06d | K6: =B6&C6&D6&E6&F6&G6&I6 -> exchangeFTXPeertecMain_Peertec10003USDT
A7: 1 | B7: exchange | C7: FTX | D7: Peertec | E7: ='(참고) Index'!$E$2 -> Main_Peertec | F7: 10003 | G7: LUNA | H7: terra1luagdjcr9c9yvp3ak4d7chjm5gldcmgln5rku5 | I7: 823031602 | J7: =H7&I7 -> terra1luagdjcr9c9yvp3ak4d7chjm5gldcmgln5rku5823031602 | K7: =B7&C7&D7&E7&F7&G7&I7 -> exchangeFTXPeertecMain_Peertec10003LUNA823031602
A8: 1 | B8: exchange | C8: FTX | D8: Peertec | E8: ='(참고) Index'!$E$2 -> Main_Peertec | F8: 10003 | G8: UST | H8: terra1luagdjcr9c9yvp3ak4d7chjm5gldcmgln5rku5 | I8: 823031602 | J8: =H8&I8 -> terra1luagdjcr9c9yvp3ak4d7chjm5gldcmgln5rku5823031602 | K8: =B8&C8&D8&E8&F8&G8&I8 -> exchangeFTXPeertecMain_Peertec10003UST823031602
A9: 1 | B9: exchange | C9: FTX | D9: Peertec | E9: ='(참고) Index'!$E$2 -> Main_Peertec | F9: 10003 | G9: ATOM | H9: cosmos1kvyevlmp0gfd7f9qdnkq98tc59p2mg2smppwn7 | I9: 3529325778 | J9: =H9&I9 -> cosmos1kvyevlmp0gfd7f9qdnkq98tc59p2mg2smppwn73529325778 | K9: =B9&C9&D9&E9&F9&G9&I9 -> exchangeFTXPeertecMain_Peertec10003ATOM3529325778
A10: 1 | B10: exchange | C10: FTX | D10: Peertec | E10: ='(참고) Index'!$E$2 -> Main_Peertec | F10: 10003 | G10: MATIC | J10: =H10&I10 | K10: =B10&C10&D10&E10&F10&G10&I10 -> exchangeFTXPeertecMain_Peertec10003MATIC
A11: 1 | B11: exchange | C11: FTX | D11: Peertec | E11: ='(참고) Index'!$E$2 -> Main_Peertec | F11: 10003 | G11: NEAR | J11: =H11&I11 | K11: =B11&C11&D11&E11&F11&G11&I11 -> exchangeFTXPeertecMain_Peertec10003NEAR
A12: 1 | B12: exchange | C12: FTX | D12: Peertec | E12: ='(참고) Index'!$E$2 -> Main_Peertec | F12: 10003 | G12: TRX | J12: =H12&I12 | K12: =B12&C12&D12&E12&F12&G12&I12 -> exchangeFTXPeertecMain_Peertec10003TRX
A13: 1 | B13: exchange | C13: FTX | D13: Peertec | E13: ='(참고) Index'!$E$2 -> Main_Peertec | F13: 10003 | G13: BCH | H13: bitcoincash:qrl59ue7seauw2lsj370zu70gq04zwsh5unkfg6scm | J13: =H13&I13 -> bitcoincash:qrl59ue7seauw2lsj370zu70gq04zwsh5unkfg6scm | K13: =B13&C13&D13&E13&F13&G13&I13 -> exchangeFTXPeertecMain_Peertec10003BCH
A14: 1 | B14: exchange | C14: FTX | D14: Peertec | E14: ='(참고) Index'!$E$2 -> Main_Peertec | F14: 10003 | G14: BNB | J14: =H14&I14 | K14: =B14&C14&D14&E14&F14&G14&I14 -> exchangeFTXPeertecMain_Peertec10003BNB
B15: exchange | C15: FTX | D15: Peertec | E15: ='(참고) Index'!$E$2 -> Main_Peertec | F15: 10003 | G15: BUSD | J15: =H15&I15 | K15: =B15&C15&D15&E15&F15&G15&I15 -> exchangeFTXPeertecMain_Peertec10003BUSD
A16: 1 | B16: exchange | C16: FTX | D16: Peertec | E16: ='(참고) Index'!$E$2 -> Main_Peertec | F16: 10003 | G16: SOL | H16: DqF4jpup3cLNkMhVxCxNqKnxxqFuVNf4zfeAnvpqdbfr | J16: =H16&I16 -> DqF4jpup3cLNkMhVxCxNqKnxxqFuVNf4zfeAnvpqdbfr | K16: =B16&C16&D16&E16&F16&G16&I16 -> exchangeFTXPeertecMain_Peertec10003SOL
A17: 1 | B17: exchange | C17: FTX | D17: Peertec | E17: ='(참고) Index'!$E$2 -> Main_Peertec | F17: 10003 | G17: LTC | J17: =H17&I17 | K17: =B17&C17&D17&E17&F17&G17&I17 -> exchangeFTXPeertecMain_Peertec10003LTC
A18: 2 | B18: exchange | C18: FTX | D18: BBRICK | E18: ='(참고) Index'!$E$3 -> Main_Bbrick | F18: 10025 | G18: BTC | H18: 3H9GcbHrica8tDjBgkByHKNbwpcdTapLoK | J18: =H18&I18 -> 3H9GcbHrica8tDjBgkByHKNbwpcdTapLoK | K18: =B18&C18&D18&E18&F18&G18&I18 -> exchangeFTXBBRICKMain_Bbrick10025BTC
A19: 2 | B19: exchange | C19: FTX | D19: BBRICK | E19: ='(참고) Index'!$E$3 -> Main_Bbrick | F19: 10025 | G19: XRP | H19: rPFXvVo2fYXVPdV9gCHQouHsMgMhQ2aUwM | I19: 3396311572 | J19: =H19&I19 -> rPFXvVo2fYXVPdV9gCHQouHsMgMhQ2aUwM3396311572 | K19: =B19&C19&D19&E19&F19&G19&I19 -> exchangeFTXBBRICKMain_Bbrick10025XRP3396311572
A20: 2 | B20: exchange | C20: FTX | D20: BBRICK | E20: ='(참고) Index'!$E$3 -> Main_Bbrick | F20: 10025 | G20: ETH | H20: 0xd16eEBDb4F8804b66AB4b2c536917154d9a47E82 | J20: =H20&I20 -> 0xd16eEBDb4F8804b66AB4b2c536917154d9a47E82 | K20: =B20&C20&D20&E20&F20&G20&I20 -> exchangeFTXBBRICKMain_Bbrick10025ETH
A21: 2 | B21: exchange | C21: FTX | D21: BBRICK | E21: ='(참고) Index'!$E$3 -> Main_Bbrick | F21: 10025 | G21: USDC | H21: 0xA341107b28740ee5a003BA3960448fD14174a026 | J21: =H21&I21 -> 0xA341107b28740ee5a003BA3960448fD14174a026 | K21: =B21&C21&D21&E21&F21&G21&I21 -> exchangeFTXBBRICKMain_Bbrick10025USDC
A22: 2 | B22: exchange | C22: FTX | D22: BBRICK | E22: ='(참고) Index'!$E$3 -> Main_Bbrick | F22: 10025 | G22: USDT | H22: 0xA341107b28740ee5a003BA3960448fD14174a026 | J22: =H22&I22 -> 0xA341107b28740ee5a003BA3960448fD14174a026 | K22: =B22&C22&D22&E22&F22&G22&I22 -> exchangeFTXBBRICKMain_Bbrick10025USDT
A23: 2 | B23: exchange | C23: FTX | D23: BBRICK | E23: ='(참고) Index'!$E$3 -> Main_Bbrick | F23: 10025 | G23: LUNA | H23: terra1luagdjcr9c9yvp3ak4d7chjm5gldcmgln5rku5 | I23: 1273090217 | J23: =H23&I23 -> terra1luagdjcr9c9yvp3ak4d7chjm5gldcmgln5rku51273090217 | K23: =B23&C23&D23&E23&F23&G23&I23 -> exchangeFTXBBRICKMain_Bbrick10025LUNA1273090217
A24: 2 | B24: exchange | C24: FTX | D24: BBRICK | E24: ='(참고) Index'!$E$3 -> Main_Bbrick | F24: 10025 | G24: UST | H24: terra1luagdjcr9c9yvp3ak4d7chjm5gldcmgln5rku5 | I24: 1273090217 | J24: =H24&I24 -> terra1luagdjcr9c9yvp3ak4d7chjm5gldcmgln5rku51273090217 | K24: =B24&C24&D24&E24&F24&G24&I24 -> exchangeFTXBBRICKMain_Bbrick10025UST1273090217
A25: 2 | B25: exchange | C25: FTX | D25: BBRICK | E25: ='(참고) Index'!$E$3 -> Main_Bbrick | F25: 10025 | G25: BNB | J25: =H25&I25 | K25: =B25&C25&D25&E25&F25&G25&I25 -> exchangeFTXBBRICKMain_Bbrick10025BNB
A26: 2 | B26: exchange | C26: FTX | D26: BBRICK | E26: ='(참고) Index'!$E$3 -> Main_Bbrick | F26: 10025 | G26: DAI | J26: =H26&I26 | K26: =B26&C26&D26&E26&F26&G26&I26 -> exchangeFTXBBRICKMain_Bbrick10025DAI
A27: 2 | B27: exchange | C27: FTX | D27: BBRICK | E27: ='(참고) Index'!$E$3 -> Main_Bbrick | F27: 10025 | G27: LTC | J27: =H27&I27 | K27: =B27&C27&D27&E27&F27&G27&I27 -> exchangeFTXBBRICKMain_Bbrick10025LTC
A28: 2 | B28: exchange | C28: FTX | D28: BBRICK | E28: ='(참고) Index'!$E$3 -> Main_Bbrick | F28: 10025 | G28: SOL | H28: Ge2iS3fXCNM3LwzECBAoHba6JgubMwB9R7NGmvSu6MuG | J28: =H28&I28 -> Ge2iS3fXCNM3LwzECBAoHba6JgubMwB9R7NGmvSu6MuG | K28: =B28&C28&D28&E28&F28&G28&I28 -> exchangeFTXBBRICKMain_Bbrick10025SOL
A29: 2 | B29: exchange | C29: FTX | D29: BBRICK | E29: ='(참고) Index'!$E$3 -> Main_Bbrick | F29: 10025 | G29: USD | J29: =H29&I29 | K29: =B29&C29&D29&E29&F29&G29&I29 -> exchangeFTXBBRICKMain_Bbrick10025USD
A30: 2 | B30: exchange | C30: FTX | D30: BBRICK | E30: ='(참고) Index'!$E$3 -> Main_Bbrick | F30: 10025 | G30: WBTC | J30: =H30&I30 | K30: =B30&C30&D30&E30&F30&G30&I30 -> exchangeFTXBBRICKMain_Bbrick10025WBTC
A31: 3 | B31: exchange | C31: FTX | D31: BBRICK | E31: ='(참고) Index'!$E$4 -> Bithumb_ETH | F31: 1 | G31: BTC | H31: 35JMNYtbvEjth4TLgiPDbhswho65ydNhVF | J31: =H31&I31 -> 35JMNYtbvEjth4TLgiPDbhswho65ydNhVF | K31: =B31&C31&D31&E31&F31&G31&I31 -> exchangeFTXBBRICKBithumb_ETH1BTC
A32: 3 | B32: exchange | C32: FTX | D32: BBRICK | E32: ='(참고) Index'!$E$4 -> Bithumb_ETH | F32: 1 | G32: XRP | H32: rPFXvVo2fYXVPdV9gCHQouHsMgMhQ2aUwM | I32: 1824918435 | J32: =H32&I32 -> rPFXvVo2fYXVPdV9gCHQouHsMgMhQ2aUwM1824918435 | K32: =B32&C32&D32&E32&F32&G32&I32 -> exchangeFTXBBRICKBithumb_ETH1XRP1824918435
A33: 3 | B33: exchange | C33: FTX | D33: BBRICK | E33: ='(참고) Index'!$E$4 -> Bithumb_ETH | F33: 1 | G33: ETH | H33: 0xAe45aBf4685B0A0a81664094896CB1e378710168 | J33: =H33&I33 -> 0xAe45aBf4685B0A0a81664094896CB1e378710168 | K33: =B33&C33&D33&E33&F33&G33&I33 -> exchangeFTXBBRICKBithumb_ETH1ETH
A34: 3 | B34: exchange | C34: FTX | D34: BBRICK | E34: ='(참고) Index'!$E$4 -> Bithumb_ETH | F34: 1 | G34: USDC | H34: 0x072f87370eFF242A1eD79907dD990846Ad934Bd8 | J34: =H34&I34 -> 0x072f87370eFF242A1eD79907dD990846Ad934Bd8 | K34: =B34&C34&D34&E34&F34&G34&I34 -> exchangeFTXBBRICKBithumb_ETH1USDC
A35: 3 | B35: exchange | C35: FTX | D35: BBRICK | E35: ='(참고) Index'!$E$4 -> Bithumb_ETH | F35: 1 | G35: USDT | H35: 0x072f87370eFF242A1eD79907dD990846Ad934Bd8 | J35: =H35&I35 -> 0x072f87370eFF242A1eD79907dD990846Ad934Bd8 | K35: =B35&C35&D35&E35&F35&G35&I35 -> exchangeFTXBBRICKBithumb_ETH1USDT
A36: 3 | B36: exchange | C36: FTX | D36: BBRICK | E36: ='(참고) Index'!$E$4 -> Bithumb_ETH | F36: 1 | G36: LUNA | H36: terra1luagdjcr9c9yvp3ak4d7chjm5gldcmgln5rku5 | I36: 614830254 | J36: =H36&I36 -> terra1luagdjcr9c9yvp3ak4d7chjm5gldcmgln5rku5614830254 | K36: =B36&C36&D36&E36&F36&G36&I36 -> exchangeFTXBBRICKBithumb_ETH1LUNA614830254
B37: exchange | C37: FTX | D37: BBRICK | E37: ='(참고) Index'!$E$4 -> Bithumb_ETH | F37: 1 | G37: TRX | H37: TQ4oJx8GtPV34vBwxErGKj2n6rmhPycYni | J37: =H37&I37 -> TQ4oJx8GtPV34vBwxErGKj2n6rmhPycYni | K37: =B37&C37&D37&E37&F37&G37&I37 -> exchangeFTXBBRICKBithumb_ETH1TRX
A38: 3 | B38: exchange | C38: FTX | D38: BBRICK | E38: ='(참고) Index'!$E$4 -> Bithumb_ETH | F38: 1 | G38: UST | H38: terra1luagdjcr9c9yvp3ak4d7chjm5gldcmgln5rku5 | I38: 614830254 | J38: =H38&I38 -> terra1luagdjcr9c9yvp3ak4d7chjm5gldcmgln5rku5614830254 | K38: =B38&C38&D38&E38&F38&G38&I38 -> exchangeFTXBBRICKBithumb_ETH1UST614830254
A39: 4 | B39: exchange | C39: FTX | D39: BBRICK | E39: ='(참고) Index'!$E$5 -> B-Brick | F39: 8 | G39: BTC | H39: 39wUrg2Sd1UG8Gey19faN4YQRPYEDpb48E | J39: =H39&I39 -> 39wUrg2Sd1UG8Gey19faN4YQRPYEDpb48E | K39: =B39&C39&D39&E39&F39&G39&I39 -> exchangeFTXBBRICKB-Brick8BTC
A40: 4 | B40: exchange | C40: FTX | D40: BBRICK | E40: ='(참고) Index'!$E$5 -> B-Brick | F40: 8 | G40: XRP | H40: rPFXvVo2fYXVPdV9gCHQouHsMgMhQ2aUwM | I40: 1464472549 | J40: =H40&I40 -> rPFXvVo2fYXVPdV9gCHQouHsMgMhQ2aUwM1464472549 | K40: =B40&C40&D40&E40&F40&G40&I40 -> exchangeFTXBBRICKB-Brick8XRP1464472549
...

Sheet 입금
A1: account type | B1: name | C1: ownership | D1: subname | E1: api id | F1: coin | G1: address | H1: tag | I1: to | J1: Deposit_Ownership | K1: Deposit_coin | L1: network | M1: quantity | N1: from | O1: from_tag | P1: from_account type | Q1: from_name | R1: from_ownership | S1: txid | T1: time | U1: Date
A2: exchange | B2: FTX | C2: BBRICK | D2: B-Brick | E2: 8 | F2: USDC | G2: =IF(INDEX(지갑!$H:$H,MATCH(A2&B2&C2&D2&E2&F2&H2,지갑!$K:$K,0))=0, "",INDEX(지갑!$H:$H,MATCH(A2&B2&C2&D2&E2&F2&H2,지갑!$K:$K,0))) -> 0xAa149A5172c5f27a8a259001AD3d62B2166Ae851 | I2: FTX | J2: BBRICK | K2: USDC | L2: ERC20 | M2: 20637800 | N2: 0x44b68b196148e426402b3e9ab3be974176ad32c0 | O2: =IF(ISERROR(INDEX(출금!$H$2:$H$1048576,MATCH($S2,출금!$S$2:$S$1048576,0)))=TRUE, "", INDEX(출금!$H$2:$H$1048576,MATCH($S2,출금!$S$2:$S$1048576,0))&"") | P2: =IF(ISERROR(INDEX(출금!$A$2:$A$1048576,MATCH($S2,출금!$S$2:$S$1048576,0)))=TRUE, "", INDEX(출금!$A$2:$A$1048576,MATCH($S2,출금!$S$2:$S$1048576,0))) | Q2: =IF(ISERROR(INDEX(출금!$B$2:$B$1048576,MATCH($S2,출금!$S$2:$S$1048576,0)))=TRUE, "", INDEX(출금!$B$2:$B$1048576,MATCH($S2,출금!$S$2:$S$1048576,0))) | R2: =IF(ISERROR(INDEX(출금!$C$2:$C$1048576,MATCH($S2,출금!$S$2:$S$1048576,0)))=TRUE, "", INDEX(출금!$C$2:$C$1048576,MATCH($S2,출금!$S$2:$S$1048576,0))) | S2: 0xca901c2b87fffea7cceb8701e6352a0b500d6738700e9ee0076128ad667fbce4 | T2: 44631.748 | U2: =TEXT(T2,"yyyy-mm-dd") -> 2022-03-11
A3: exchange | B3: FTX | C3: BBRICK | D3: B-Brick | E3: 8 | F3: USDC | G3: =IF(INDEX(지갑!$H:$H,MATCH(A3&B3&C3&D3&E3&F3&H3,지갑!$K:$K,0))=0, "",INDEX(지갑!$H:$H,MATCH(A3&B3&C3&D3&E3&F3&H3,지갑!$K:$K,0))) -> 0xAa149A5172c5f27a8a259001AD3d62B2166Ae851 | I3: FTX | J3: BBRICK | K3: USDC | L3: ERC20 | M3: 8491319 | N3: 0x44b68b196148e426402b3e9ab3be974176ad32c0 | O3: =IF(ISERROR(INDEX(출금!$H$2:$H$1048576,MATCH($S3,출금!$S$2:$S$1048576,0)))=TRUE, "", INDEX(출금!$H$2:$H$1048576,MATCH($S3,출금!$S$2:$S$1048576,0))&"") | P3: =IF(ISERROR(INDEX(출금!$A$2:$A$1048576,MATCH($S3,출금!$S$2:$S$1048576,0)))=TRUE, "", INDEX(출금!$A$2:$A$1048576,MATCH($S3,출금!$S$2:$S$1048576,0))) | Q3: =IF(ISERROR(INDEX(출금!$B$2:$B$1048576,MATCH($S3,출금!$S$2:$S$1048576,0)))=TRUE, "", INDEX(출금!$B$2:$B$1048576,MATCH($S3,출금!$S$2:$S$1048576,0))) | R3: =IF(ISERROR(INDEX(출금!$C$2:$C$1048576,MATCH($S3,출금!$S$2:$S$1048576,0)))=TRUE, "", INDEX(출금!$C$2:$C$1048576,MATCH($S3,출금!$S$2:$S$1048576,0))) | S3: 0xf2f1e89f40e73e228cea3db35b841552f9494f46333387fb72501370a5532a93 | T3: 44628.538 | U3: =TEXT(T3,"yyyy-mm-dd") -> 2022-03-08
A4: exchange | B4: FTX | C4: BBRICK | D4: B-Brick | E4: 8 | F4: USDC | G4: =IF(INDEX(지갑!$H:$H,MATCH(A4&B4&C4&D4&E4&F4&H4,지갑!$K:$K,0))=0, "",INDEX(지갑!$H:$H,MATCH(A4&B4&C4&D4&E4&F4&H4,지갑!$K:$K,0))) -> 0xAa149A5172c5f27a8a259001AD3d62B2166Ae851 | I4: FTX | J4: BBRICK | K4: USDC | L4: ERC20 | M4: 10 | N4: 0x44b68b196148e426402b3e9ab3be974176ad32c0 | O4: =IF(ISERROR(INDEX(출금!$H$2:$H$1048576,MATCH($S4,출금!$S$2:$S$1048576,0)))=TRUE, "", INDEX(출금!$H$2:$H$1048576,MATCH($S4,출금!$S$2:$S$1048576,0))&"") | P4: =IF(ISERROR(INDEX(출금!$A$2:$A$1048576,MATCH($S4,출금!$S$2:$S$1048576,0)))=TRUE, "", INDEX(출금!$A$2:$A$1048576,MATCH($S4,출금!$S$2:$S$1048576,0))) | Q4: =IF(ISERROR(INDEX(출금!$B$2:$B$1048576,MATCH($S4,출금!$S$2:$S$1048576,0)))=TRUE, "", INDEX(출금!$B$2:$B$1048576,MATCH($S4,출금!$S$2:$S$1048576,0))) | R4: =IF(ISERROR(INDEX(출금!$C$2:$C$1048576,MATCH($S4,출금!$S$2:$S$1048576,0)))=TRUE, "", INDEX(출금!$C$2:$C$1048576,MATCH($S4,출금!$S$2:$S$1048576,0))) | S4: 0x71ebc28929e3f55b839f7a3a40eed3aaa891bacedccd143e57e1e8b2a1fb4ffd | T4: 44628.451 | U4: =TEXT(T4,"yyyy-mm-dd") -> 2022-03-08
A5: exchange | B5: Huobi | C5: Peertec | F5: =K5 -> ETH | G5: =IF(INDEX(지갑!$H:$H,MATCH(A5&B5&C5&D5&E5&F5&H5,지갑!$K:$K,0))=0, "",INDEX(지갑!$H:$H,MATCH(A5&B5&C5&D5&E5&F5&H5,지갑!$K:$K,0))) -> 0xdb245cf0aec8bf5d4b3002d00f3e701e80ba380a | I5: Huobi | J5: Peertec | K5: ETH | L5: ETH | M5: 249.99 | N5: 0x97122ddca38c29b7653d52b07998d06a7128fa0b | O5: =IF(ISERROR(INDEX(출금!$H$2:$H$1048576,MATCH($S5,출금!$S$2:$S$1048576,0)))=TRUE, "", INDEX(출금!$H$2:$H$1048576,MATCH($S5,출금!$S$2:$S$1048576,0))&"") | P5: =IF(ISERROR(INDEX(출금!$A$2:$A$1048576,MATCH($S5,출금!$S$2:$S$1048576,0)))=TRUE, "", INDEX(출금!$A$2:$A$1048576,MATCH($S5,출금!$S$2:$S$1048576,0))) | Q5: =IF(ISERROR(INDEX(출금!$B$2:$B$1048576,MATCH($S5,출금!$S$2:$S$1048576,0)))=TRUE, "", INDEX(출금!$B$2:$B$1048576,MATCH($S5,출금!$S$2:$S$1048576,0))) | R5: =IF(ISERROR(INDEX(출금!$C$2:$C$1048576,MATCH($S5,출금!$S$2:$S$1048576,0)))=TRUE, "", INDEX(출금!$C$2:$C$1048576,MATCH($S5,출금!$S$2:$S$1048576,0))) | S5: af3a9795b83dd46101b341f7c10046fec83b22e3e84cf39d2d64c7ae6356c572 | T5: 44232.773 | U5: =TEXT(T5,"yyyy-mm-dd") -> 2021-02-05
A6: exchange | B6: FTX | C6: BBRICK | D6: B-Brick | E6: 8 | F6: ETH | G6: =IF(INDEX(지갑!$H:$H,MATCH(A6&B6&C6&D6&E6&F6&H6,지갑!$K:$K,0))=0, "",INDEX(지갑!$H:$H,MATCH(A6&B6&C6&D6&E6&F6&H6,지갑!$K:$K,0))) -> 0xBA7600fa3507c8f357C6206B645385D7e4723895 | I6: FTX | J6: BBRICK | K6: ETH | L6: ETH | M6: 2390.1163 | N6: 0xc168062c9c958e01914c7e3885537541dbb9ed08 | O6: =IF(ISERROR(INDEX(출금!$H$2:$H$1048576,MATCH($S6,출금!$S$2:$S$1048576,0)))=TRUE, "", INDEX(출금!$H$2:$H$1048576,MATCH($S6,출금!$S$2:$S$1048576,0))&"") | P6: =IF(ISERROR(INDEX(출금!$A$2:$A$1048576,MATCH($S6,출금!$S$2:$S$1048576,0)))=TRUE, "", INDEX(출금!$A$2:$A$1048576,MATCH($S6,출금!$S$2:$S$1048576,0))) | Q6: =IF(ISERROR(INDEX(출금!$B$2:$B$1048576,MATCH($S6,출금!$S$2:$S$1048576,0)))=TRUE, "", INDEX(출금!$B$2:$B$1048576,MATCH($S6,출금!$S$2:$S$1048576,0))) | R6: =IF(ISERROR(INDEX(출금!$C$2:$C$1048576,MATCH($S6,출금!$S$2:$S$1048576,0)))=TRUE, "", INDEX(출금!$C$2:$C$1048576,MATCH($S6,출금!$S$2:$S$1048576,0))) | S6: 0xdd1194b1aa66f21200313ac0fbc08bfab4344825491ea0b8e327e3edd79aaf9d | T6: 44614.602 | U6: =TEXT(T6,"yyyy-mm-dd") -> 2022-02-22
A7: exchange | B7: FTX | C7: BBRICK | D7: B-Brick | E7: 8 | F7: ETH | G7: =IF(INDEX(지갑!$H:$H,MATCH(A7&B7&C7&D7&E7&F7&H7,지갑!$K:$K,0))=0, "",INDEX(지갑!$H:$H,MATCH(A7&B7&C7&D7&E7&F7&H7,지갑!$K:$K,0))) -> 0xBA7600fa3507c8f357C6206B645385D7e4723895 | I7: FTX | J7: BBRICK | K7: ETH | L7: ETH | M7: 4200 | N7: 0xafadc4302f07e9460eb4c31ec741c0f3e308ff3a | O7: =IF(ISERROR(INDEX(출금!$H$2:$H$1048576,MATCH($S7,출금!$S$2:$S$1048576,0)))=TRUE, "", INDEX(출금!$H$2:$H$1048576,MATCH($S7,출금!$S$2:$S$1048576,0))&"") | P7: =IF(ISERROR(INDEX(출금!$A$2:$A$1048576,MATCH($S7,출금!$S$2:$S$1048576,0)))=TRUE, "", INDEX(출금!$A$2:$A$1048576,MATCH($S7,출금!$S$2:$S$1048576,0))) | Q7: =IF(ISERROR(INDEX(출금!$B$2:$B$1048576,MATCH($S7,출금!$S$2:$S$1048576,0)))=TRUE, "", INDEX(출금!$B$2:$B$1048576,MATCH($S7,출금!$S$2:$S$1048576,0))) | R7: =IF(ISERROR(INDEX(출금!$C$2:$C$1048576,MATCH($S7,출금!$S$2:$S$1048576,0)))=TRUE, "", INDEX(출금!$C$2:$C$1048576,MATCH($S7,출금!$S$2:$S$1048576,0))) | S7: 0xf2fa7849093bc059c5b015bf23d6aa75b68c1cc7cc57a95d939c86694ce41640 | T7: 44614.581 | U7: =TEXT(T7,"yyyy-mm-dd") -> 2022-02-22
A8: exchange | B8: FTX | C8: BBRICK | D8: B-Brick | E8: 8 | F8: USD | G8: =IF(INDEX(지갑!$H:$H,MATCH(A8&B8&C8&D8&E8&F8&H8,지갑!$K:$K,0))=0, "",INDEX(지갑!$H:$H,MATCH(A8&B8&C8&D8&E8&F8&H8,지갑!$K:$K,0))) -> #N/A | I8: FTX | J8: BBRICK | K8: USD | M8: 1110350.2 | N8: =IF(ISERROR(INDEX(출금!$G$2:$G$1048576,MATCH($S8,출금!$S$2:$S$1048576,0)))=TRUE, "", INDEX(출금!$G$2:$G$1048576,MATCH($S8,출금!$S$2:$S$1048576,0))&"") | O8: =IF(ISERROR(INDEX(출금!$H$2:$H$1048576,MATCH($S8,출금!$S$2:$S$1048576,0)))=TRUE, "", INDEX(출금!$H$2:$H$1048576,MATCH($S8,출금!$S$2:$S$1048576,0))&"") | P8: =IF(ISERROR(INDEX(출금!$A$2:$A$1048576,MATCH($S8,출금!$S$2:$S$1048576,0)))=TRUE, "", INDEX(출금!$A$2:$A$1048576,MATCH($S8,출금!$S$2:$S$1048576,0))) | Q8: =IF(ISERROR(INDEX(출금!$B$2:$B$1048576,MATCH($S8,출금!$S$2:$S$1048576,0)))=TRUE, "", INDEX(출금!$B$2:$B$1048576,MATCH($S8,출금!$S$2:$S$1048576,0))) | R8: =IF(ISERROR(INDEX(출금!$C$2:$C$1048576,MATCH($S8,출금!$S$2:$S$1048576,0)))=TRUE, "", INDEX(출금!$C$2:$C$1048576,MATCH($S8,출금!$S$2:$S$1048576,0))) | T8: 44579.426 | U8: =TEXT(T8,"yyyy-mm-dd") -> 2022-01-18
A9: exchange | B9: FTX | C9: BBRICK | D9: B-Brick | E9: 8 | F9: USD | G9: =IF(INDEX(지갑!$H:$H,MATCH(A9&B9&C9&D9&E9&F9&H9,지갑!$K:$K,0))=0, "",INDEX(지갑!$H:$H,MATCH(A9&B9&C9&D9&E9&F9&H9,지갑!$K:$K,0))) -> #N/A | I9: FTX | J9: BBRICK | K9: USD | M9: 110350.18 | N9: =IF(ISERROR(INDEX(출금!$G$2:$G$1048576,MATCH($S9,출금!$S$2:$S$1048576,0)))=TRUE, "", INDEX(출금!$G$2:$G$1048576,MATCH($S9,출금!$S$2:$S$1048576,0))&"") | O9: =IF(ISERROR(INDEX(출금!$H$2:$H$1048576,MATCH($S9,출금!$S$2:$S$1048576,0)))=TRUE, "", INDEX(출금!$H$2:$H$1048576,MATCH($S9,출금!$S$2:$S$1048576,0))&"") | P9: =IF(ISERROR(INDEX(출금!$A$2:$A$1048576,MATCH($S9,출금!$S$2:$S$1048576,0)))=TRUE, "", INDEX(출금!$A$2:$A$1048576,MATCH($S9,출금!$S$2:$S$1048576,0))) | Q9: =IF(ISERROR(INDEX(출금!$B$2:$B$1048576,MATCH($S9,출금!$S$2:$S$1048576,0)))=TRUE, "", INDEX(출금!$B$2:$B$1048576,MATCH($S9,출금!$S$2:$S$1048576,0))) | R9: =IF(ISERROR(INDEX(출금!$C$2:$C$1048576,MATCH($S9,출금!$S$2:$S$1048576,0)))=TRUE, "", INDEX(출금!$C$2:$C$1048576,MATCH($S9,출금!$S$2:$S$1048576,0))) | T9: 44579.426 | U9: =TEXT(T9,"yyyy-mm-dd") -> 2022-01-18
A10: exchange | B10: FTX | C10: BBRICK | D10: B-Brick | E10: 8 | F10: SOL | G10: =IF(INDEX(지갑!$H:$H,MATCH(A10&B10&C10&D10&E10&F10&H10,지갑!$K:$K,0))=0, "",INDEX(지갑!$H:$H,MATCH(A10&B10&C10&D10&E10&F10&H10,지갑!$K:$K,0))) -> 4WALSVwxUyuXkxFqSwcweEgh2ddYjYoaFw3yUw3GMDPK | I10: FTX | J10: BBRICK | K10: SOL | M10: 1497.5786 | N10: =IF(ISERROR(INDEX(출금!$G$2:$G$1048576,MATCH($S10,출금!$S$2:$S$1048576,0)))=TRUE, "", INDEX(출금!$G$2:$G$1048576,MATCH($S10,출금!$S$2:$S$1048576,0))&"") | O10: =IF(ISERROR(INDEX(출금!$H$2:$H$1048576,MATCH($S10,출금!$S$2:$S$1048576,0)))=TRUE, "", INDEX(출금!$H$2:$H$1048576,MATCH($S10,출금!$S$2:$S$1048576,0))&"") | P10: =IF(ISERROR(INDEX(출금!$A$2:$A$1048576,MATCH($S10,출금!$S$2:$S$1048576,0)))=TRUE, "", INDEX(출금!$A$2:$A$1048576,MATCH($S10,출금!$S$2:$S$1048576,0))) | Q10: =IF(ISERROR(INDEX(출금!$B$2:$B$1048576,MATCH($S10,출금!$S$2:$S$1048576,0)))=TRUE, "", INDEX(출금!$B$2:$B$1048576,MATCH($S10,출금!$S$2:$S$1048576,0))) | R10: =IF(ISERROR(INDEX(출금!$C$2:$C$1048576,MATCH($S10,출금!$S$2:$S$1048576,0)))=TRUE, "", INDEX(출금!$C$2:$C$1048576,MATCH($S10,출금!$S$2:$S$1048576,0))) | T10: 44579.426 | U10: =TEXT(T10,"yyyy-mm-dd") -> 2022-01-18
A11: exchange | B11: FTX | C11: BBRICK | D11: B-Brick | E11: 8 | F11: USD | G11: =IF(INDEX(지갑!$H:$H,MATCH(A11&B11&C11&D11&E11&F11&H11,지갑!$K:$K,0))=0, "",INDEX(지갑!$H:$H,MATCH(A11&B11&C11&D11&E11&F11&H11,지갑!$K:$K,0))) -> #N/A | I11: FTX | J11: BBRICK | K11: USD | M11: 1497.5786 | N11: =IF(ISERROR(INDEX(출금!$G$2:$G$1048576,MATCH($S11,출금!$S$2:$S$1048576,0)))=TRUE, "", INDEX(출금!$G$2:$G$1048576,MATCH($S11,출금!$S$2:$S$1048576,0))&"") | O11: =IF(ISERROR(INDEX(출금!$H$2:$H$1048576,MATCH($S11,출금!$S$2:$S$1048576,0)))=TRUE, "", INDEX(출금!$H$2:$H$1048576,MATCH($S11,출금!$S$2:$S$1048576,0))&"") | P11: =IF(ISERROR(INDEX(출금!$A$2:$A$1048576,MATCH($S11,출금!$S$2:$S$1048576,0)))=TRUE, "", INDEX(출금!$A$2:$A$1048576,MATCH($S11,출금!$S$2:$S$1048576,0))) | Q11: =IF(ISERROR(INDEX(출금!$B$2:$B$1048576,MATCH($S11,출금!$S$2:$S$1048576,0)))=TRUE, "", INDEX(출금!$B$2:$B$1048576,MATCH($S11,출금!$S$2:$S$1048576,0))) | R11: =IF(ISERROR(INDEX(출금!$C$2:$C$1048576,MATCH($S11,출금!$S$2:$S$1048576,0)))=TRUE, "", INDEX(출금!$C$2:$C$1048576,MATCH($S11,출금!$S$2:$S$1048576,0))) | T11: 44579.426 | U11: =TEXT(T11,"yyyy-mm-dd") -> 2022-01-18
A12: exchange | B12: FTX | C12: BBRICK | D12: B-Brick | E12: 8 | F12: SOL | G12: =IF(INDEX(지갑!$H:$H,MATCH(A12&B12&C12&D12&E12&F12&H12,지갑!$K:$K,0))=0, "",INDEX(지갑!$H:$H,MATCH(A12&B12&C12&D12&E12&F12&H12,지갑!$K:$K,0))) -> 4WALSVwxUyuXkxFqSwcweEgh2ddYjYoaFw3yUw3GMDPK | I12: FTX | J12: BBRICK | K12: SOL | M12: 1497.5786 | N12: =IF(ISERROR(INDEX(출금!$G$2:$G$1048576,MATCH($S12,출금!$S$2:$S$1048576,0)))=TRUE, "", INDEX(출금!$G$2:$G$1048576,MATCH($S12,출금!$S$2:$S$1048576,0))&"") | O12: =IF(ISERROR(INDEX(출금!$H$2:$H$1048576,MATCH($S12,출금!$S$2:$S$1048576,0)))=TRUE, "", INDEX(출금!$H$2:$H$1048576,MATCH($S12,출금!$S$2:$S$1048576,0))&"") | P12: =IF(ISERROR(INDEX(출금!$A$2:$A$1048576,MATCH($S12,출금!$S$2:$S$1048576,0)))=TRUE, "", INDEX(출금!$A$2:$A$1048576,MATCH($S12,출금!$S$2:$S$1048576,0))) | Q12: =IF(ISERROR(INDEX(출금!$B$2:$B$1048576,MATCH($S12,출금!$S$2:$S$1048576,0)))=TRUE, "", INDEX(출금!$B$2:$B$1048576,MATCH($S12,출금!$S$2:$S$1048576,0))) | R12: =IF(ISERROR(INDEX(출금!$C$2:$C$1048576,MATCH($S12,출금!$S$2:$S$1048576,0)))=TRUE, "", INDEX(출금!$C$2:$C$1048576,MATCH($S12,출금!$S$2:$S$1048576,0))) | T12: 44578.41 | U12: =TEXT(T12,"yyyy-mm-dd") -> 2022-01-17
A13: exchange | B13: FTX | C13: BBRICK | D13: B-Brick | E13: 8 | F13: USD | G13: =IF(INDEX(지갑!$H:$H,MATCH(A13&B13&C13&D13&E13&F13&H13,지갑!$K:$K,0))=0, "",INDEX(지갑!$H:$H,MATCH(A13&B13&C13&D13&E13&F13&H13,지갑!$K:$K,0))) -> #N/A | I13: FTX | J13: BBRICK | K13: USD | M13: 1512134 | N13: =IF(ISERROR(INDEX(출금!$G$2:$G$1048576,MATCH($S13,출금!$S$2:$S$1048576,0)))=TRUE, "", INDEX(출금!$G$2:$G$1048576,MATCH($S13,출금!$S$2:$S$1048576,0))&"") | O13: =IF(ISERROR(INDEX(출금!$H$2:$H$1048576,MATCH($S13,출금!$S$2:$S$1048576,0)))=TRUE, "", INDEX(출금!$H$2:$H$1048576,MATCH($S13,출금!$S$2:$S$1048576,0))&"") | P13: =IF(ISERROR(INDEX(출금!$A$2:$A$1048576,MATCH($S13,출금!$S$2:$S$1048576,0)))=TRUE, "", INDEX(출금!$A$2:$A$1048576,MATCH($S13,출금!$S$2:$S$1048576,0))) | Q13: =IF(ISERROR(INDEX(출금!$B$2:$B$1048576,MATCH($S13,출금!$S$2:$S$1048576,0)))=TRUE, "", INDEX(출금!$B$2:$B$1048576,MATCH($S13,출금!$S$2:$S$1048576,0))) | R13: =IF(ISERROR(INDEX(출금!$C$2:$C$1048576,MATCH($S13,출금!$S$2:$S$1048576,0)))=TRUE, "", INDEX(출금!$C$2:$C$1048576,MATCH($S13,출금!$S$2:$S$1048576,0))) | T13: 44578.404 | U13: =TEXT(T13,"yyyy-mm-dd") -> 2022-01-17
A14: exchange | B14: FTX | C14: BBRICK | D14: B-Brick | E14: 8 | F14: BUSD | G14: =IF(INDEX(지갑!$H:$H,MATCH(A14&B14&C14&D14&E14&F14&H14,지갑!$K:$K,0))=0, "",INDEX(지갑!$H:$H,MATCH(A14&B14&C14&D14&E14&F14&H14,지갑!$K:$K,0))) -> #N/A | I14: FTX | J14: BBRICK | K14: BUSD | L14: BSC | M14: 1463218 | N14: 0xa3479d004c339ab1bc8a5873b5657e7aecd6af461f3b01bea3a572073b290689 (Binance: Hot Wallet 6) | O14: =IF(ISERROR(INDEX(출금!$H$2:$H$1048576,MATCH($S14,출금!$S$2:$S$1048576,0)))=TRUE, "", INDEX(출금!$H$2:$H$1048576,MATCH($S14,출금!$S$2:$S$1048576,0))&"") | P14: =IF(ISERROR(INDEX(출금!$A$2:$A$1048576,MATCH($S14,출금!$S$2:$S$1048576,0)))=TRUE, "", INDEX(출금!$A$2:$A$1048576,MATCH($S14,출금!$S$2:$S$1048576,0))) -> exchange | Q14: =IF(ISERROR(INDEX(출금!$B$2:$B$1048576,MATCH($S14,출금!$S$2:$S$1048576,0)))=TRUE, "", INDEX(출금!$B$2:$B$1048576,MATCH($S14,출금!$S$2:$S$1048576,0))) -> Binance | R14: =IF(ISERROR(INDEX(출금!$C$2:$C$1048576,MATCH($S14,출금!$S$2:$S$1048576,0)))=TRUE, "", INDEX(출금!$C$2:$C$1048576,MATCH($S14,출금!$S$2:$S$1048576,0))) -> BBRICK | S14: 0xa3479d004c339ab1bc8a5873b5657e7aecd6af461f3b01bea3a572073b290689 | T14: 44561.563 | U14: =TEXT(T14,"yyyy-mm-dd") -> 2021-12-31
A15: exchange | B15: OKEX | C15: Peertec | F15: KLAY | G15: =IF(INDEX(지갑!$H:$H,MATCH(A15&B15&C15&D15&E15&F15&H15,지갑!$K:$K,0))=0, "",INDEX(지갑!$H:$H,MATCH(A15&B15&C15&D15&E15&F15&H15,지갑!$K:$K,0))) -> 0x5006bc0d4fa0117e93d21aa663969fc6703a4319 | I15: OKEX | J15: Peertec | K15: KLAY | L15: KLAY | M15: 7901.1188 | N15: 0x980e9dfeaa8ea715e97827bb770fac8b97090ef1 | O15: =IF(ISERROR(INDEX(출금!$H$2:$H$1048576,MATCH($S15,출금!$S$2:$S$1048576,0)))=TRUE, "", INDEX(출금!$H$2:$H$1048576,MATCH($S15,출금!$S$2:$S$1048576,0))&"") | P15: =IF(ISERROR(INDEX(출금!$A$2:$A$1048576,MATCH($S15,출금!$S$2:$S$1048576,0)))=TRUE, "", INDEX(출금!$A$2:$A$1048576,MATCH($S15,출금!$S$2:$S$1048576,0))) | Q15: =IF(ISERROR(INDEX(출금!$B$2:$B$1048576,MATCH($S15,출금!$S$2:$S$1048576,0)))=TRUE, "", INDEX(출금!$B$2:$B$1048576,MATCH($S15,출금!$S$2:$S$1048576,0))) | R15: =IF(ISERROR(INDEX(출금!$C$2:$C$1048576,MATCH($S15,출금!$S$2:$S$1048576,0)))=TRUE, "", INDEX(출금!$C$2:$C$1048576,MATCH($S15,출금!$S$2:$S$1048576,0))) | S15: 0x1149ea5ef99a22a9d4d04c65e21daf9e25d35dbaf2098171774817032b1914b7 | T15: 44646.193 | U15: =TEXT(T15,"yyyy-mm-dd") -> 2022-03-26
A16: exchange | B16: FTX | C16: BBRICK | D16: B-Brick | E16: 8 | F16: SOL | G16: =IF(INDEX(지갑!$H:$H,MATCH(A16&B16&C16&D16&E16&F16&H16,지갑!$K:$K,0))=0, "",INDEX(지갑!$H:$H,MATCH(A16&B16&C16&D16&E16&F16&H16,지갑!$K:$K,0))) -> 4WALSVwxUyuXkxFqSwcweEgh2ddYjYoaFw3yUw3GMDPK | I16: FTX | J16: BBRICK | K16: SOL | M16: 1497.5786 | N16: =IF(ISERROR(INDEX(출금!$G$2:$G$1048576,MATCH($S16,출금!$S$2:$S$1048576,0)))=TRUE, "", INDEX(출금!$G$2:$G$1048576,MATCH($S16,출금!$S$2:$S$1048576,0))&"") | O16: =IF(ISERROR(INDEX(출금!$H$2:$H$1048576,MATCH($S16,출금!$S$2:$S$1048576,0)))=TRUE, "", INDEX(출금!$H$2:$H$1048576,MATCH($S16,출금!$S$2:$S$1048576,0))&"") | P16: =IF(ISERROR(INDEX(출금!$A$2:$A$1048576,MATCH($S16,출금!$S$2:$S$1048576,0)))=TRUE, "", INDEX(출금!$A$2:$A$1048576,MATCH($S16,출금!$S$2:$S$1048576,0))) | Q16: =IF(ISERROR(INDEX(출금!$B$2:$B$1048576,MATCH($S16,출금!$S$2:$S$1048576,0)))=TRUE, "", INDEX(출금!$B$2:$B$1048576,MATCH($S16,출금!$S$2:$S$1048576,0))) | R16: =IF(ISERROR(INDEX(출금!$C$2:$C$1048576,MATCH($S16,출금!$S$2:$S$1048576,0)))=TRUE, "", INDEX(출금!$C$2:$C$1048576,MATCH($S16,출금!$S$2:$S$1048576,0))) | T16: 44561.508 | U16: =TEXT(T16,"yyyy-mm-dd") -> 2021-12-31
A17: exchange | B17: FTX | C17: BBRICK | D17: B-Brick | E17: 8 | F17: BTC | G17: =IF(INDEX(지갑!$H:$H,MATCH(A17&B17&C17&D17&E17&F17&H17,지갑!$K:$K,0))=0, "",INDEX(지갑!$H:$H,MATCH(A17&B17&C17&D17&E17&F17&H17,지갑!$K:$K,0))) -> 39wUrg2Sd1UG8Gey19faN4YQRPYEDpb48E | I17: FTX | J17: BBRICK | K17: BTC | M17: 7.3130319 | N17: =IF(ISERROR(INDEX(출금!$G$2:$G$1048576,MATCH($S17,출금!$S$2:$S$1048576,0)))=TRUE, "", INDEX(출금!$G$2:$G$1048576,MATCH($S17,출금!$S$2:$S$1048576,0))&"") | O17: =IF(ISERROR(INDEX(출금!$H$2:$H$1048576,MATCH($S17,출금!$S$2:$S$1048576,0)))=TRUE, "", INDEX(출금!$H$2:$H$1048576,MATCH($S17,출금!$S$2:$S$1048576,0))&"") | P17: =IF(ISERROR(INDEX(출금!$A$2:$A$1048576,MATCH($S17,출금!$S$2:$S$1048576,0)))=TRUE, "", INDEX(출금!$A$2:$A$1048576,MATCH($S17,출금!$S$2:$S$1048576,0))) | Q17: =IF(ISERROR(INDEX(출금!$B$2:$B$1048576,MATCH($S17,출금!$S$2:$S$1048576,0)))=TRUE, "", INDEX(출금!$B$2:$B$1048576,MATCH($S17,출금!$S$2:$S$1048576,0))) | R17: =IF(ISERROR(INDEX(출금!$C$2:$C$1048576,MATCH($S17,출금!$S$2:$S$1048576,0)))=TRUE, "", INDEX(출금!$C$2:$C$1048576,MATCH($S17,출금!$S$2:$S$1048576,0))) | T17: 44477.608 | U17: =TEXT(T17,"yyyy-mm-dd") -> 2021-10-08
A18: exchange | B18: OKEX | C18: Peertec | F18: USDT | G18: =IF(INDEX(지갑!$H:$H,MATCH(A18&B18&C18&D18&E18&F18&H18,지갑!$K:$K,0))=0, "",INDEX(지갑!$H:$H,MATCH(A18&B18&C18&D18&E18&F18&H18,지갑!$K:$K,0))) -> 0x5006bc0d4fa0117e93d21aa663969fc6703a4319 | I18: OKEX | J18: Peertec | K18: USDT | L18: TRON | M18: 100 | N18: =IF(ISERROR(INDEX(출금!$G$2:$G$1048576,MATCH($S18,출금!$S$2:$S$1048576,0)))=TRUE, "", INDEX(출금!$G$2:$G$1048576,MATCH($S18,출금!$S$2:$S$1048576,0))&"") -> 0xA341107b28740ee5a003BA3960448fD14174a026 | O18: =IF(ISERROR(INDEX(출금!$H$2:$H$1048576,MATCH($S18,출금!$S$2:$S$1048576,0)))=TRUE, "", INDEX(출금!$H$2:$H$1048576,MATCH($S18,출금!$S$2:$S$1048576,0))&"") | P18: =IF(ISERROR(INDEX(출금!$A$2:$A$1048576,MATCH($S18,출금!$S$2:$S$1048576,0)))=TRUE, "", INDEX(출금!$A$2:$A$1048576,MATCH($S18,출금!$S$2:$S$1048576,0))) -> exchange | Q18: =IF(ISERROR(INDEX(출금!$B$2:$B$1048576,MATCH($S18,출금!$S$2:$S$1048576,0)))=TRUE, "", INDEX(출금!$B$2:$B$1048576,MATCH($S18,출금!$S$2:$S$1048576,0))) -> FTX | R18: =IF(ISERROR(INDEX(출금!$C$2:$C$1048576,MATCH($S18,출금!$S$2:$S$1048576,0)))=TRUE, "", INDEX(출금!$C$2:$C$1048576,MATCH($S18,출금!$S$2:$S$1048576,0))) -> BBRICK | S18: 2e38fa3e38e04b21edba9a15a00c1bcc18ba93ca3984463d0ce565ff056ff80f | T18: 44647.91 | U18: =TEXT(T18,"yyyy-mm-dd") -> 2022-03-27
A19: Wallet | B19: Terra | C19: BBRICK | D19: 비브릭용_Terra_wallet | G19: =IF(INDEX(지갑!$H:$H,MATCH(A19&B19&C19&D19&E19&F19&H19,지갑!$K:$K,0))=0, "",INDEX(지갑!$H:$H,MATCH(A19&B19&C19&D19&E19&F19&H19,지갑!$K:$K,0))) -> terra174evzq0tnd0uvzkkrvg08n9geqpcsvdrychcm8 | I19: Terra | J19: BBRICK | K19: Luna | L19: TERRA | M19: 9.98 | N19: =IF(ISERROR(INDEX(출금!$G$2:$G$1048576,MATCH($S19,출금!$S$2:$S$1048576,0)))=TRUE, "", INDEX(출금!$G$2:$G$1048576,MATCH($S19,출금!$S$2:$S$1048576,0))&"") -> terra1ncjg4a59x2pgvqy9qjyqprlj8lrwshm0wleht5 | O19: =IF(ISERROR(INDEX(출금!$H$2:$H$1048576,MATCH($S19,출금!$S$2:$S$1048576,0)))=TRUE, "", INDEX(출금!$H$2:$H$1048576,MATCH($S19,출금!$S$2:$S$1048576,0))&"") -> 102585224 | P19: =IF(ISERROR(INDEX(출금!$A$2:$A$1048576,MATCH($S19,출금!$S$2:$S$1048576,0)))=TRUE, "", INDEX(출금!$A$2:$A$1048576,MATCH($S19,출금!$S$2:$S$1048576,0))) -> exchange | Q19: =IF(ISERROR(INDEX(출금!$B$2:$B$1048576,MATCH($S19,출금!$S$2:$S$1048576,0)))=TRUE, "", INDEX(출금!$B$2:$B$1048576,MATCH($S19,출금!$S$2:$S$1048576,0))) -> Binance | R19: =IF(ISERROR(INDEX(출금!$C$2:$C$1048576,MATCH($S19,출금!$S$2:$S$1048576,0)))=TRUE, "", INDEX(출금!$C$2:$C$1048576,MATCH($S19,출금!$S$2:$S$1048576,0))) -> BBRICK | S19: B1CA82D9B8741FBBE0C9274A99FBDC8B2A8363C2AEA508C6AB43C7175DD6CA66 | T19: 44478.494 | U19: =TEXT(T19,"yyyy-mm-dd") -> 2021-10-09
A20: exchange | B20: OKEX | C20: Peertec | F20: KLAY | G20: =IF(INDEX(지갑!$H:$H,MATCH(A20&B20&C20&D20&E20&F20&H20,지갑!$K:$K,0))=0, "",INDEX(지갑!$H:$H,MATCH(A20&B20&C20&D20&E20&F20&H20,지갑!$K:$K,0))) -> 0x5006bc0d4fa0117e93d21aa663969fc6703a4319 | I20: OKEX | J20: Peertec | K20: KLAY | L20: KLAY | M20: 40.431743 | N20: 0x980e9dfeaa8ea715e97827bb770fac8b97090ef1 | O20: =IF(ISERROR(INDEX(출금!$H$2:$H$1048576,MATCH($S20,출금!$S$2:$S$1048576,0)))=TRUE, "", INDEX(출금!$H$2:$H$1048576,MATCH($S20,출금!$S$2:$S$1048576,0))&"") | P20: =IF(ISERROR(INDEX(출금!$A$2:$A$1048576,MATCH($S20,출금!$S$2:$S$1048576,0)))=TRUE, "", INDEX(출금!$A$2:$A$1048576,MATCH($S20,출금!$S$2:$S$1048576,0))) | Q20: =IF(ISERROR(INDEX(출금!$B$2:$B$1048576,MATCH($S20,출금!$S$2:$S$1048576,0)))=TRUE, "", INDEX(출금!$B$2:$B$1048576,MATCH($S20,출금!$S$2:$S$1048576,0))) | R20: =IF(ISERROR(INDEX(출금!$C$2:$C$1048576,MATCH($S20,출금!$S$2:$S$1048576,0)))=TRUE, "", INDEX(출금!$C$2:$C$1048576,MATCH($S20,출금!$S$2:$S$1048576,0))) | S20: 0x3a52ff0b68ef3e5e0b32ebf4649cc2d9424ae155b8071ccd09427d126a1e140f | T20: 44648.347 | U20: =TEXT(T20,"yyyy-mm-dd") -> 2022-03-28
A21: exchange | B21: FTX | C21: BBRICK | D21: B-Brick | E21: 8 | F21: USD | G21: =IF(INDEX(지갑!$H:$H,MATCH(A21&B21&C21&D21&E21&F21&H21,지갑!$K:$K,0))=0, "",INDEX(지갑!$H:$H,MATCH(A21&B21&C21&D21&E21&F21&H21,지갑!$K:$K,0))) -> #N/A | I21: FTX | J21: BBRICK | K21: USD | M21: 200000 | N21: =IF(ISERROR(INDEX(출금!$G$2:$G$1048576,MATCH($S21,출금!$S$2:$S$1048576,0)))=TRUE, "", INDEX(출금!$G$2:$G$1048576,MATCH($S21,출금!$S$2:$S$1048576,0))&"") | O21: =IF(ISERROR(INDEX(출금!$H$2:$H$1048576,MATCH($S21,출금!$S$2:$S$1048576,0)))=TRUE, "", INDEX(출금!$H$2:$H$1048576,MATCH($S21,출금!$S$2:$S$1048576,0))&"") | P21: =IF(ISERROR(INDEX(출금!$A$2:$A$1048576,MATCH($S21,출금!$S$2:$S$1048576,0)))=TRUE, "", INDEX(출금!$A$2:$A$1048576,MATCH($S21,출금!$S$2:$S$1048576,0))) | Q21: =IF(ISERROR(INDEX(출금!$B$2:$B$1048576,MATCH($S21,출금!$S$2:$S$1048576,0)))=TRUE, "", INDEX(출금!$B$2:$B$1048576,MATCH($S21,출금!$S$2:$S$1048576,0))) | R21: =IF(ISERROR(INDEX(출금!$C$2:$C$1048576,MATCH($S21,출금!$S$2:$S$1048576,0)))=TRUE, "", INDEX(출금!$C$2:$C$1048576,MATCH($S21,출금!$S$2:$S$1048576,0))) | T21: 44175.379 | U21: =TEXT(T21,"yyyy-mm-dd") -> 2020-12-10
A22: exchange | B22: FTX | C22: BBRICK | D22: B-Brick | E22: 8 | F22: USD | G22: =IF(INDEX(지갑!$H:$H,MATCH(A22&B22&C22&D22&E22&F22&H22,지갑!$K:$K,0))=0, "",INDEX(지갑!$H:$H,MATCH(A22&B22&C22&D22&E22&F22&H22,지갑!$K:$K,0))) -> #N/A | I22: FTX | J22: BBRICK | K22: USD | M22: 10000 | N22: =IF(ISERROR(INDEX(출금!$G$2:$G$1048576,MATCH($S22,출금!$S$2:$S$1048576,0)))=TRUE, "", INDEX(출금!$G$2:$G$1048576,MATCH($S22,출금!$S$2:$S$1048576,0))&"") | O22: =IF(ISERROR(INDEX(출금!$H$2:$H$1048576,MATCH($S22,출금!$S$2:$S$1048576,0)))=TRUE, "", INDEX(출금!$H$2:$H$1048576,MATCH($S22,출금!$S$2:$S$1048576,0))&"") | P22: =IF(ISERROR(INDEX(출금!$A$2:$A$1048576,MATCH($S22,출금!$S$2:$S$1048576,0)))=TRUE, "", INDEX(출금!$A$2:$A$1048576,MATCH($S22,출금!$S$2:$S$1048576,0))) | Q22: =IF(ISERROR(INDEX(출금!$B$2:$B$1048576,MATCH($S22,출금!$S$2:$S$1048576,0)))=TRUE, "", INDEX(출금!$B$2:$B$1048576,MATCH($S22,출금!$S$2:$S$1048576,0))) | R22: =IF(ISERROR(INDEX(출금!$C$2:$C$1048576,MATCH($S22,출금!$S$2:$S$1048576,0)))=TRUE, "", INDEX(출금!$C$2:$C$1048576,MATCH($S22,출금!$S$2:$S$1048576,0))) | T22: 44168.476 | U22: =TEXT(T22,"yyyy-mm-dd") -> 2020-12-03
A23: exchange | B23: OKEX | C23: Peertec | F23: ETC | G23: =IF(INDEX(지갑!$H:$H,MATCH(A23&B23&C23&D23&E23&F23&H23,지갑!$K:$K,0))=0, "",INDEX(지갑!$H:$H,MATCH(A23&B23&C23&D23&E23&F23&H23,지갑!$K:$K,0))) -> 0x4972a657d735e8ff5c2cfd2a7a5299100091f900? | I23: OKEX | J23: Peertec | K23: ETC | L23: ETC | M23: 55.838991 | N23: =IF(ISERROR(INDEX(출금!$G$2:$G$1048576,MATCH($S23,출금!$S$2:$S$1048576,0)))=TRUE, "", INDEX(출금!$G$2:$G$1048576,MATCH($S23,출금!$S$2:$S$1048576,0))&"") | O23: =IF(ISERROR(INDEX(출금!$H$2:$H$1048576,MATCH($S23,출금!$S$2:$S$1048576,0)))=TRUE, "", INDEX(출금!$H$2:$H$1048576,MATCH($S23,출금!$S$2:$S$1048576,0))&"") | P23: =IF(ISERROR(INDEX(출금!$A$2:$A$1048576,MATCH($S23,출금!$S$2:$S$1048576,0)))=TRUE, "", INDEX(출금!$A$2:$A$1048576,MATCH($S23,출금!$S$2:$S$1048576,0))) | Q23: =IF(ISERROR(INDEX(출금!$B$2:$B$1048576,MATCH($S23,출금!$S$2:$S$1048576,0)))=TRUE, "", INDEX(출금!$B$2:$B$1048576,MATCH($S23,출금!$S$2:$S$1048576,0))) | R23: =IF(ISERROR(INDEX(출금!$C$2:$C$1048576,MATCH($S23,출금!$S$2:$S$1048576,0)))=TRUE, "", INDEX(출금!$C$2:$C$1048576,MATCH($S23,출금!$S$2:$S$1048576,0))) | S23: 0x1af0c1f70aa0aab493c51111d00bb42f22e876932807c34f73162d02ea4d4281 | T23: 44650.403 | U23: =TEXT(T23,"yyyy-mm-dd") -> 2022-03-30
A24: exchange | B24: FTX | C24: BBRICK | D24: Bithumb | E24: 7 | F24: BNB | G24: =IF(INDEX(지갑!$H:$H,MATCH(A24&B24&C24&D24&E24&F24&H24,지갑!$K:$K,0))=0, "",INDEX(지갑!$H:$H,MATCH(A24&B24&C24&D24&E24&F24&H24,지갑!$K:$K,0))) -> #N/A | I24: FTX | J24: BBRICK | K24: BNB | M24: 100 | N24: =IF(ISERROR(INDEX(출금!$G$2:$G$1048576,MATCH($S24,출금!$S$2:$S$1048576,0)))=TRUE, "", INDEX(출금!$G$2:$G$1048576,MATCH($S24,출금!$S$2:$S$1048576,0))&"") | O24: =IF(ISERROR(INDEX(출금!$H$2:$H$1048576,MATCH($S24,출금!$S$2:$S$1048576,0)))=TRUE, "", INDEX(출금!$H$2:$H$1048576,MATCH($S24,출금!$S$2:$S$1048576,0))&"") | P24: =IF(ISERROR(INDEX(출금!$A$2:$A$1048576,MATCH($S24,출금!$S$2:$S$1048576,0)))=TRUE, "", INDEX(출금!$A$2:$A$1048576,MATCH($S24,출금!$S$2:$S$1048576,0))) | Q24: =IF(ISERROR(INDEX(출금!$B$2:$B$1048576,MATCH($S24,출금!$S$2:$S$1048576,0)))=TRUE, "", INDEX(출금!$B$2:$B$1048576,MATCH($S24,출금!$S$2:$S$1048576,0))) | R24: =IF(ISERROR(INDEX(출금!$C$2:$C$1048576,MATCH($S24,출금!$S$2:$S$1048576,0)))=TRUE, "", INDEX(출금!$C$2:$C$1048576,MATCH($S24,출금!$S$2:$S$1048576,0))) | T24: 44568.915 | U24: =TEXT(T24,"yyyy-mm-dd") -> 2022-01-07
A25: exchange | B25: OKEX | C25: Peertec | F25: KLAY | G25: =IF(INDEX(지갑!$H:$H,MATCH(A25&B25&C25&D25&E25&F25&H25,지갑!$K:$K,0))=0, "",INDEX(지갑!$H:$H,MATCH(A25&B25&C25&D25&E25&F25&H25,지갑!$K:$K,0))) -> 0x5006bc0d4fa0117e93d21aa663969fc6703a4319 | I25: OKEX | J25: Peertec | K25: KLAY | L25: KLAY | M25: 3336.2992 | N25: =IF(ISERROR(INDEX(출금!$G$2:$G$1048576,MATCH($S25,출금!$S$2:$S$1048576,0)))=TRUE, "", INDEX(출금!$G$2:$G$1048576,MATCH($S25,출금!$S$2:$S$1048576,0))&"") | O25: =IF(ISERROR(INDEX(출금!$H$2:$H$1048576,MATCH($S25,출금!$S$2:$S$1048576,0)))=TRUE, "", INDEX(출금!$H$2:$H$1048576,MATCH($S25,출금!$S$2:$S$1048576,0))&"") | P25: =IF(ISERROR(INDEX(출금!$A$2:$A$1048576,MATCH($S25,출금!$S$2:$S$1048576,0)))=TRUE, "", INDEX(출금!$A$2:$A$1048576,MATCH($S25,출금!$S$2:$S$1048576,0))) | Q25: =IF(ISERROR(INDEX(출금!$B$2:$B$1048576,MATCH($S25,출금!$S$2:$S$1048576,0)))=TRUE, "", INDEX(출금!$B$2:$B$1048576,MATCH($S25,출금!$S$2:$S$1048576,0))) | R25: =IF(ISERROR(INDEX(출금!$C$2:$C$1048576,MATCH($S25,출금!$S$2:$S$1048576,0)))=TRUE, "", INDEX(출금!$C$2:$C$1048576,MATCH($S25,출금!$S$2:$S$1048576,0))) | S25: 0x24002ac340feb36276a502abea542d98a9609ebafe0e24950159e0ac6cc8c14c | T25: 44651.605 | U25: =TEXT(T25,"yyyy-mm-dd") -> 2022-03-31
A26: exchange | B26: Huobi | C26: Peertec | F26: =K26 -> BTC | G26: =IF(INDEX(지갑!$H:$H,MATCH(A26&B26&C26&D26&E26&F26&H26,지갑!$K:$K,0))=0, "",INDEX(지갑!$H:$H,MATCH(A26&B26&C26&D26&E26&F26&H26,지갑!$K:$K,0))) -> 1MdatewJkKfSptYBaJvgEBFYCEbiCkELVt | I26: Huobi | J26: Peertec | K26: BTC | L26: BTC | M26: 9.999 | N26: =IF(ISERROR(INDEX(출금!$G$2:$G$1048576,MATCH($S26,출금!$S$2:$S$1048576,0)))=TRUE, "", INDEX(출금!$G$2:$G$1048576,MATCH($S26,출금!$S$2:$S$1048576,0))&"") | O26: =IF(ISERROR(INDEX(출금!$H$2:$H$1048576,MATCH($S26,출금!$S$2:$S$1048576,0)))=TRUE, "", INDEX(출금!$H$2:$H$1048576,MATCH($S26,출금!$S$2:$S$1048576,0))&"") | P26: =IF(ISERROR(INDEX(출금!$A$2:$A$1048576,MATCH($S26,출금!$S$2:$S$1048576,0)))=TRUE, "", INDEX(출금!$A$2:$A$1048576,MATCH($S26,출금!$S$2:$S$1048576,0))) | Q26: =IF(ISERROR(INDEX(출금!$B$2:$B$1048576,MATCH($S26,출금!$S$2:$S$1048576,0)))=TRUE, "", INDEX(출금!$B$2:$B$1048576,MATCH($S26,출금!$S$2:$S$1048576,0))) | R26: =IF(ISERROR(INDEX(출금!$C$2:$C$1048576,MATCH($S26,출금!$S$2:$S$1048576,0)))=TRUE, "", INDEX(출금!$C$2:$C$1048576,MATCH($S26,출금!$S$2:$S$1048576,0))) | S26: c5bf3d207c6d5f31760dcf12de54d28fd2a0d624c102b7b73c83b61bfaff2857 | T26: 44232.79 | U26: =TEXT(T26,"yyyy-mm-dd") -> 2021-02-05
A27: exchange | B27: FTX | C27: BBRICK | D27: Bithumb | E27: 7 | F27: USDT | G27: =IF(INDEX(지갑!$H:$H,MATCH(A27&B27&C27&D27&E27&F27&H27,지갑!$K:$K,0))=0, "",INDEX(지갑!$H:$H,MATCH(A27&B27&C27&D27&E27&F27&H27,지갑!$K:$K,0))) -> 0xCe17482d83FD53E2A921186Bd6ddd412610F7A1f | I27: FTX | J27: BBRICK | K27: USDT | M27: 50000 | N27: =IF(ISERROR(INDEX(출금!$G$2:$G$1048576,MATCH($S27,출금!$S$2:$S$1048576,0)))=TRUE, "", INDEX(출금!$G$2:$G$1048576,MATCH($S27,출금!$S$2:$S$1048576,0))&"") | O27: =IF(ISERROR(INDEX(출금!$H$2:$H$1048576,MATCH($S27,출금!$S$2:$S$1048576,0)))=TRUE, "", INDEX(출금!$H$2:$H$1048576,MATCH($S27,출금!$S$2:$S$1048576,0))&"") | P27: =IF(ISERROR(INDEX(출금!$A$2:$A$1048576,MATCH($S27,출금!$S$2:$S$1048576,0)))=TRUE, "", INDEX(출금!$A$2:$A$1048576,MATCH($S27,출금!$S$2:$S$1048576,0))) | Q27: =IF(ISERROR(INDEX(출금!$B$2:$B$1048576,MATCH($S27,출금!$S$2:$S$1048576,0)))=TRUE, "", INDEX(출금!$B$2:$B$1048576,MATCH($S27,출금!$S$2:$S$1048576,0))) | R27: =IF(ISERROR(INDEX(출금!$C$2:$C$1048576,MATCH($S27,출금!$S$2:$S$1048576,0)))=TRUE, "", INDEX(출금!$C$2:$C$1048576,MATCH($S27,출금!$S$2:$S$1048576,0))) | T27: 44568.915 | U27: =TEXT(T27,"yyyy-mm-dd") -> 2022-01-07
A28: exchange | B28: OKEX | C28: Peertec | F28: KLAY | G28: =IF(INDEX(지갑!$H:$H,MATCH(A28&B28&C28&D28&E28&F28&H28,지갑!$K:$K,0))=0, "",INDEX(지갑!$H:$H,MATCH(A28&B28&C28&D28&E28&F28&H28,지갑!$K:$K,0))) -> 0x5006bc0d4fa0117e93d21aa663969fc6703a4319 | I28: OKEX | J28: Peertec | K28: KLAY | L28: KLAY | M28: 368.88561 | N28: =IF(ISERROR(INDEX(출금!$G$2:$G$1048576,MATCH($S28,출금!$S$2:$S$1048576,0)))=TRUE, "", INDEX(출금!$G$2:$G$1048576,MATCH($S28,출금!$S$2:$S$1048576,0))&"") | O28: =IF(ISERROR(INDEX(출금!$H$2:$H$1048576,MATCH($S28,출금!$S$2:$S$1048576,0)))=TRUE, "", INDEX(출금!$H$2:$H$1048576,MATCH($S28,출금!$S$2:$S$1048576,0))&"") | P28: =IF(ISERROR(INDEX(출금!$A$2:$A$1048576,MATCH($S28,출금!$S$2:$S$1048576,0)))=TRUE, "", INDEX(출금!$A$2:$A$1048576,MATCH($S28,출금!$S$2:$S$1048576,0))) | Q28: =IF(ISERROR(INDEX(출금!$B$2:$B$1048576,MATCH($S28,출금!$S$2:$S$1048576,0)))=TRUE, "", INDEX(출금!$B$2:$B$1048576,MATCH($S28,출금!$S$2:$S$1048576,0))) | R28: =IF(ISERROR(INDEX(출금!$C$2:$C$1048576,MATCH($S28,출금!$S$2:$S$1048576,0)))=TRUE, "", INDEX(출금!$C$2:$C$1048576,MATCH($S28,출금!$S$2:$S$1048576,0))) | S28: 0x6a685666a848cd04e240a06ea1777d5e080ebb5842dee373b93bf3b474c12a73 | T28: 44652.405 | U28: =TEXT(T28,"yyyy-mm-dd") -> 2022-04-01
A29: Wallet | B29: Terra | C29: BBRICK | D29: 비브릭용_Terra_wallet | G29: =IF(INDEX(지갑!$H:$H,MATCH(A29&B29&C29&D29&E29&F29&H29,지갑!$K:$K,0))=0, "",INDEX(지갑!$H:$H,MATCH(A29&B29&C29&D29&E29&F29&H29,지갑!$K:$K,0))) -> terra174evzq0tnd0uvzkkrvg08n9geqpcsvdrychcm8 | I29: Terra | J29: BBRICK | K29: UST | L29: TERRA | M29: 41.79 | N29: =IF(ISERROR(INDEX(출금!$G$2:$G$1048576,MATCH($S29,출금!$S$2:$S$1048576,0)))=TRUE, "", INDEX(출금!$G$2:$G$1048576,MATCH($S29,출금!$S$2:$S$1048576,0))&"") | O29: =IF(ISERROR(INDEX(출금!$H$2:$H$1048576,MATCH($S29,출금!$S$2:$S$1048576,0)))=TRUE, "", INDEX(출금!$H$2:$H$1048576,MATCH($S29,출금!$S$2:$S$1048576,0))&"") | P29: =IF(ISERROR(INDEX(출금!$A$2:$A$1048576,MATCH($S29,출금!$S$2:$S$1048576,0)))=TRUE, "", INDEX(출금!$A$2:$A$1048576,MATCH($S29,출금!$S$2:$S$1048576,0))) | Q29: =IF(ISERROR(INDEX(출금!$B$2:$B$1048576,MATCH($S29,출금!$S$2:$S$1048576,0)))=TRUE, "", INDEX(출금!$B$2:$B$1048576,MATCH($S29,출금!$S$2:$S$1048576,0))) | R29: =IF(ISERROR(INDEX(출금!$C$2:$C$1048576,MATCH($S29,출금!$S$2:$S$1048576,0)))=TRUE, "", INDEX(출금!$C$2:$C$1048576,MATCH($S29,출금!$S$2:$S$1048576,0))) | S29: 35A121273CA223DB68B0F4FE17B1D5F24C2F8E2726AD679E8C405072437CFF2E | T29: 44479.446 | U29: =TEXT(T29,"yyyy-mm-dd") -> 2021-10-10
A30: exchange | B30: FTX | C30: BBRICK | D30: Bithumb | E30: 7 | F30: ETH | G30: =IF(INDEX(지갑!$H:$H,MATCH(A30&B30&C30&D30&E30&F30&H30,지갑!$K:$K,0))=0, "",INDEX(지갑!$H:$H,MATCH(A30&B30&C30&D30&E30&F30&H30,지갑!$K:$K,0))) -> 0x87b88FB60b6429DB66ADd58aB6C909A1C715E346 | I30: FTX | J30: BBRICK | K30: ETH | M30: 10 | N30: =IF(ISERROR(INDEX(출금!$G$2:$G$1048576,MATCH($S30,출금!$S$2:$S$1048576,0)))=TRUE, "", INDEX(출금!$G$2:$G$1048576,MATCH($S30,출금!$S$2:$S$1048576,0))&"") | O30: =IF(ISERROR(INDEX(출금!$H$2:$H$1048576,MATCH($S30,출금!$S$2:$S$1048576,0)))=TRUE, "", INDEX(출금!$H$2:$H$1048576,MATCH($S30,출금!$S$2:$S$1048576,0))&"") | P30: =IF(ISERROR(INDEX(출금!$A$2:$A$1048576,MATCH($S30,출금!$S$2:$S$1048576,0)))=TRUE, "", INDEX(출금!$A$2:$A$1048576,MATCH($S30,출금!$S$2:$S$1048576,0))) | Q30: =IF(ISERROR(INDEX(출금!$B$2:$B$1048576,MATCH($S30,출금!$S$2:$S$1048576,0)))=TRUE, "", INDEX(출금!$B$2:$B$1048576,MATCH($S30,출금!$S$2:$S$1048576,0))) | R30: =IF(ISERROR(INDEX(출금!$C$2:$C$1048576,MATCH($S30,출금!$S$2:$S$1048576,0)))=TRUE, "", INDEX(출금!$C$2:$C$1048576,MATCH($S30,출금!$S$2:$S$1048576,0))) | T30: 44568.914 | U30: =TEXT(T30,"yyyy-mm-dd") -> 2022-01-07
A31: exchange | B31: FTX | C31: BBRICK | D31: Bithumb | E31: 7 | F31: BTC | G31: =IF(INDEX(지갑!$H:$H,MATCH(A31&B31&C31&D31&E31&F31&H31,지갑!$K:$K,0))=0, "",INDEX(지갑!$H:$H,MATCH(A31&B31&C31&D31&E31&F31&H31,지갑!$K:$K,0))) -> 3LLRS688CkBg71m4qvEffbHh9sMQZfH5or | I31: FTX | J31: BBRICK | K31: BTC | L31: BTC | M31: 86.706938 | N31: =IF(ISERROR(INDEX(출금!$G$2:$G$1048576,MATCH($S31,출금!$S$2:$S$1048576,0)))=TRUE, "", INDEX(출금!$G$2:$G$1048576,MATCH($S31,출금!$S$2:$S$1048576,0))&"") -> 1MdatewJkKfSptYBaJvgEBFYCEbiCkELVt | O31: =IF(ISERROR(INDEX(출금!$H$2:$H$1048576,MATCH($S31,출금!$S$2:$S$1048576,0)))=TRUE, "", INDEX(출금!$H$2:$H$1048576,MATCH($S31,출금!$S$2:$S$1048576,0))&"") | P31: =IF(ISERROR(INDEX(출금!$A$2:$A$1048576,MATCH($S31,출금!$S$2:$S$1048576,0)))=TRUE, "", INDEX(출금!$A$2:$A$1048576,MATCH($S31,출금!$S$2:$S$1048576,0))) -> exchange | Q31: =IF(ISERROR(INDEX(출금!$B$2:$B$1048576,MATCH($S31,출금!$S$2:$S$1048576,0)))=TRUE, "", INDEX(출금!$B$2:$B$1048576,MATCH($S31,출금!$S$2:$S$1048576,0))) -> Huobi | R31: =IF(ISERROR(INDEX(출금!$C$2:$C$1048576,MATCH($S31,출금!$S$2:$S$1048576,0)))=TRUE, "", INDEX(출금!$C$2:$C$1048576,MATCH($S31,출금!$S$2:$S$1048576,0))) -> Peertec | S31: 637d7d46d77fb54bd69a8ba6da94ef3b1c68466c0b29793fb8d50975ee7d92ef | T31: 44565.849 | U31: =TEXT(T31,"yyyy-mm-dd") -> 2022-01-04
A32: exchange | B32: FTX | C32: BBRICK | D32: Bithumb | E32: 7 | F32: BTC | G32: =IF(INDEX(지갑!$H:$H,MATCH(A32&B32&C32&D32&E32&F32&H32,지갑!$K:$K,0))=0, "",INDEX(지갑!$H:$H,MATCH(A32&B32&C32&D32&E32&F32&H32,지갑!$K:$K,0))) -> 3LLRS688CkBg71m4qvEffbHh9sMQZfH5or | I32: FTX | J32: BBRICK | K32: BTC | L32: BTC | M32: 287.12601 | N32: =IF(ISERROR(INDEX(출금!$G$2:$G$1048576,MATCH($S32,출금!$S$2:$S$1048576,0)))=TRUE, "", INDEX(출금!$G$2:$G$1048576,MATCH($S32,출금!$S$2:$S$1048576,0))&"") | O32: =IF(ISERROR(INDEX(출금!$H$2:$H$1048576,MATCH($S32,출금!$S$2:$S$1048576,0)))=TRUE, "", INDEX(출금!$H$2:$H$1048576,MATCH($S32,출금!$S$2:$S$1048576,0))&"") | P32: =IF(ISERROR(INDEX(출금!$A$2:$A$1048576,MATCH($S32,출금!$S$2:$S$1048576,0)))=TRUE, "", INDEX(출금!$A$2:$A$1048576,MATCH($S32,출금!$S$2:$S$1048576,0))) | Q32: =IF(ISERROR(INDEX(출금!$B$2:$B$1048576,MATCH($S32,출금!$S$2:$S$1048576,0)))=TRUE, "", INDEX(출금!$B$2:$B$1048576,MATCH($S32,출금!$S$2:$S$1048576,0))) | R32: =IF(ISERROR(INDEX(출금!$C$2:$C$1048576,MATCH($S32,출금!$S$2:$S$1048576,0)))=TRUE, "", INDEX(출금!$C$2:$C$1048576,MATCH($S32,출금!$S$2:$S$1048576,0))) | S32: b4198e30f515922967c0a9df9f6b0b14567440424987a3755d674a771dd98cd9 | T32: 44564.588 | U32: =TEXT(T32,"yyyy-mm-dd") -> 2022-01-03
A33: exchange | B33: FTX | C33: BBRICK | D33: Bithumb | E33: 7 | F33: SOL | G33: =IF(INDEX(지갑!$H:$H,MATCH(A33&B33&C33&D33&E33&F33&H33,지갑!$K:$K,0))=0, "",INDEX(지갑!$H:$H,MATCH(A33&B33&C33&D33&E33&F33&H33,지갑!$K:$K,0))) -> HFaX33KAtC9knovpb1xsMXfV971D8L4Qhf66XzozYGww | I33: FTX | J33: BBRICK | K33: SOL | L33: SOL | M33: 1392.35 | N33: =IF(ISERROR(INDEX(출금!$G$2:$G$1048576,MATCH($S33,출금!$S$2:$S$1048576,0)))=TRUE, "", INDEX(출금!$G$2:$G$1048576,MATCH($S33,출금!$S$2:$S$1048576,0))&"") -> SUZXwKfyPi8U4nMJNvT6b7WgDkaKmHvfVT9uE3yZYjx | O33: =IF(ISERROR(INDEX(출금!$H$2:$H$1048576,MATCH($S33,출금!$S$2:$S$1048576,0)))=TRUE, "", INDEX(출금!$H$2:$H$1048576,MATCH($S33,출금!$S$2:$S$1048576,0))&"") | P33: =IF(ISERROR(INDEX(출금!$A$2:$A$1048576,MATCH($S33,출금!$S$2:$S$1048576,0)))=TRUE, "", INDEX(출금!$A$2:$A$1048576,MATCH($S33,출금!$S$2:$S$1048576,0))) -> exchange | Q33: =IF(ISERROR(INDEX(출금!$B$2:$B$1048576,MATCH($S33,출금!$S$2:$S$1048576,0)))=TRUE, "", INDEX(출금!$B$2:$B$1048576,MATCH($S33,출금!$S$2:$S$1048576,0))) -> Binance | R33: =IF(ISERROR(INDEX(출금!$C$2:$C$1048576,MATCH($S33,출금!$S$2:$S$1048576,0)))=TRUE, "", INDEX(출금!$C$2:$C$1048576,MATCH($S33,출금!$S$2:$S$1048576,0))) -> BBRICK | S33: KP5Gtd4xFrbTZjBicdcA7XJKSJmJK3Sn6UuaSqEGrG9owYofemYFMKURxyF4TQ4N1Rj2GaCZ5x7Kmxerd3uTyvL | T33: 44561.458 | U33: =TEXT(T33,"yyyy-mm-dd") -> 2021-12-31
A34: exchange | B34: FTX | C34: BBRICK | D34: Bithumb | E34: 7 | F34: ETH | G34: =IF(INDEX(지갑!$H:$H,MATCH(A34&B34&C34&D34&E34&F34&H34,지갑!$K:$K,0))=0, "",INDEX(지갑!$H:$H,MATCH(A34&B34&C34&D34&E34&F34&H34,지갑!$K:$K,0))) -> 0x87b88FB60b6429DB66ADd58aB6C909A1C715E346 | I34: FTX | J34: BBRICK | K34: ETH | L34: ETH | M34: 4452.9275 | N34: 0xdc5432c573a1d4874d305a5cd7e62aed2b0bc522 | O34: =IF(ISERROR(INDEX(출금!$H$2:$H$1048576,MATCH($S34,출금!$S$2:$S$1048576,0)))=TRUE, "", INDEX(출금!$H$2:$H$1048576,MATCH($S34,출금!$S$2:$S$1048576,0))&"") | P34: =IF(ISERROR(INDEX(출금!$A$2:$A$1048576,MATCH($S34,출금!$S$2:$S$1048576,0)))=TRUE, "", INDEX(출금!$A$2:$A$1048576,MATCH($S34,출금!$S$2:$S$1048576,0))) | Q34: =IF(ISERROR(INDEX(출금!$B$2:$B$1048576,MATCH($S34,출금!$S$2:$S$1048576,0)))=TRUE, "", INDEX(출금!$B$2:$B$1048576,MATCH($S34,출금!$S$2:$S$1048576,0))) | R34: =IF(ISERROR(INDEX(출금!$C$2:$C$1048576,MATCH($S34,출금!$S$2:$S$1048576,0)))=TRUE, "", INDEX(출금!$C$2:$C$1048576,MATCH($S34,출금!$S$2:$S$1048576,0))) | S34: 0x9821f31820059106963ee5176058b34cc215dcf5626ee55e071459daa163edb4 | T34: 44553.44 | U34: =TEXT(T34,"yyyy-mm-dd") -> 2021-12-23
A35: exchange | B35: FTX | C35: BBRICK | D35: Bithumb | E35: 7 | F35: SOL | G35: =IF(INDEX(지갑!$H:$H,MATCH(A35&B35&C35&D35&E35&F35&H35,지갑!$K:$K,0))=0, "",INDEX(지갑!$H:$H,MATCH(A35&B35&C35&D35&E35&F35&H35,지갑!$K:$K,0))) -> HFaX33KAtC9knovpb1xsMXfV971D8L4Qhf66XzozYGww | I35: FTX | J35: BBRICK | K35: SOL | L35: SOL | M35: 99.95 | N35: =IF(ISERROR(INDEX(출금!$G$2:$G$1048576,MATCH($S35,출금!$S$2:$S$1048576,0)))=TRUE, "", INDEX(출금!$G$2:$G$1048576,MATCH($S35,출금!$S$2:$S$1048576,0))&"") | O35: =IF(ISERROR(INDEX(출금!$H$2:$H$1048576,MATCH($S35,출금!$S$2:$S$1048576,0)))=TRUE, "", INDEX(출금!$H$2:$H$1048576,MATCH($S35,출금!$S$2:$S$1048576,0))&"") | P35: =IF(ISERROR(INDEX(출금!$A$2:$A$1048576,MATCH($S35,출금!$S$2:$S$1048576,0)))=TRUE, "", INDEX(출금!$A$2:$A$1048576,MATCH($S35,출금!$S$2:$S$1048576,0))) | Q35: =IF(ISERROR(INDEX(출금!$B$2:$B$1048576,MATCH($S35,출금!$S$2:$S$1048576,0)))=TRUE, "", INDEX(출금!$B$2:$B$1048576,MATCH($S35,출금!$S$2:$S$1048576,0))) | R35: =IF(ISERROR(INDEX(출금!$C$2:$C$1048576,MATCH($S35,출금!$S$2:$S$1048576,0)))=TRUE, "", INDEX(출금!$C$2:$C$1048576,MATCH($S35,출금!$S$2:$S$1048576,0))) | S35: 55PepaBZVkNKhxr7J5v6asCQyZx4H3HDhwxnbG13uGb6aL7tHYjCS96dooa7hQvmBAgQqBXrmbiZS48HJsi9a9H7 | T35: 44552.626 | U35: =TEXT(T35,"yyyy-mm-dd") -> 2021-12-22
A36: exchange | B36: FTX | C36: BBRICK | D36: Bithumb | E36: 7 | F36: USDC | G36: =IF(INDEX(지갑!$H:$H,MATCH(A36&B36&C36&D36&E36&F36&H36,지갑!$K:$K,0))=0, "",INDEX(지갑!$H:$H,MATCH(A36&B36&C36&D36&E36&F36&H36,지갑!$K:$K,0))) -> 0xCe17482d83FD53E2A921186Bd6ddd412610F7A1f | I36: FTX | J36: BBRICK | K36: USDC | L36: SOL | M36: 1000080.2 | N36: =IF(ISERROR(INDEX(출금!$G$2:$G$1048576,MATCH($S36,출금!$S$2:$S$1048576,0)))=TRUE, "", INDEX(출금!$G$2:$G$1048576,MATCH($S36,출금!$S$2:$S$1048576,0))&"") -> TJrPnAJbrzjfqKtGgQ24Yg7p4kaWg73wAT | O36: =IF(ISERROR(INDEX(출금!$H$2:$H$1048576,MATCH($S36,출금!$S$2:$S$1048576,0)))=TRUE, "", INDEX(출금!$H$2:$H$1048576,MATCH($S36,출금!$S$2:$S$1048576,0))&"") | P36: =IF(ISERROR(INDEX(출금!$A$2:$A$1048576,MATCH($S36,출금!$S$2:$S$1048576,0)))=TRUE, "", INDEX(출금!$A$2:$A$1048576,MATCH($S36,출금!$S$2:$S$1048576,0))) -> exchange | Q36: =IF(ISERROR(INDEX(출금!$B$2:$B$1048576,MATCH($S36,출금!$S$2:$S$1048576,0)))=TRUE, "", INDEX(출금!$B$2:$B$1048576,MATCH($S36,출금!$S$2:$S$1048576,0))) -> Huobi | R36: =IF(ISERROR(INDEX(출금!$C$2:$C$1048576,MATCH($S36,출금!$S$2:$S$1048576,0)))=TRUE, "", INDEX(출금!$C$2:$C$1048576,MATCH($S36,출금!$S$2:$S$1048576,0))) -> Peertec | S36: 5LSxtofmdBzu4PDm8iLjk1e581ELvLuEsubLkbB6QS76nD2FrfC5deNbsbBHmMFap2iYaCJgbNFNKNLsNtCHU65M | T36: 44544.258 | U36: =TEXT(T36,"yyyy-mm-dd") -> 2021-12-14
A37: exchange | B37: FTX | C37: BBRICK | D37: Bithumb | E37: 7 | F37: USDC | G37: =IF(INDEX(지갑!$H:$H,MATCH(A37&B37&C37&D37&E37&F37&H37,지갑!$K:$K,0))=0, "",INDEX(지갑!$H:$H,MATCH(A37&B37&C37&D37&E37&F37&H37,지갑!$K:$K,0))) -> 0xCe17482d83FD53E2A921186Bd6ddd412610F7A1f | I37: FTX | J37: BBRICK | K37: USDC | L37: ERC20 | M37: 65705.852 | N37: 0x02074984dab902181b4263f52f6b5437f011b606 | O37: =IF(ISERROR(INDEX(출금!$H$2:$H$1048576,MATCH($S37,출금!$S$2:$S$1048576,0)))=TRUE, "", INDEX(출금!$H$2:$H$1048576,MATCH($S37,출금!$S$2:$S$1048576,0))&"") | P37: =IF(ISERROR(INDEX(출금!$A$2:$A$1048576,MATCH($S37,출금!$S$2:$S$1048576,0)))=TRUE, "", INDEX(출금!$A$2:$A$1048576,MATCH($S37,출금!$S$2:$S$1048576,0))) | Q37: =IF(ISERROR(INDEX(출금!$B$2:$B$1048576,MATCH($S37,출금!$S$2:$S$1048576,0)))=TRUE, "", INDEX(출금!$B$2:$B$1048576,MATCH($S37,출금!$S$2:$S$1048576,0))) | R37: =IF(ISERROR(INDEX(출금!$C$2:$C$1048576,MATCH($S37,출금!$S$2:$S$1048576,0)))=TRUE, "", INDEX(출금!$C$2:$C$1048576,MATCH($S37,출금!$S$2:$S$1048576,0))) | S37: 0x02d0147820b62d8b8c6c88bd1d26148b213c4668b6555067860319a45f89f3e6 | T37: 44543.793 | U37: =TEXT(T37,"yyyy-mm-dd") -> 2021-12-13
A38: exchange | B38: FTX | C38: BBRICK | D38: Bithumb | E38: 7 | F38: BTC | G38: =IF(INDEX(지갑!$H:$H,MATCH(A38&B38&C38&D38&E38&F38&H38,지갑!$K:$K,0))=0, "",INDEX(지갑!$H:$H,MATCH(A38&B38&C38&D38&E38&F38&H38,지갑!$K:$K,0))) -> 3LLRS688CkBg71m4qvEffbHh9sMQZfH5or | I38: FTX | J38: BBRICK | K38: BTC | L38: BTC | M38: 99.9995 | N38: =IF(ISERROR(INDEX(출금!$G$2:$G$1048576,MATCH($S38,출금!$S$2:$S$1048576,0)))=TRUE, "", INDEX(출금!$G$2:$G$1048576,MATCH($S38,출금!$S$2:$S$1048576,0))&"") -> 19SK9LWSXLdmwPxvjPgvUrdaPhaPS6LaNu | O38: =IF(ISERROR(INDEX(출금!$H$2:$H$1048576,MATCH($S38,출금!$S$2:$S$1048576,0)))=TRUE, "", INDEX(출금!$H$2:$H$1048576,MATCH($S38,출금!$S$2:$S$1048576,0))&"") | P38: =IF(ISERROR(INDEX(출금!$A$2:$A$1048576,MATCH($S38,출금!$S$2:$S$1048576,0)))=TRUE, "", INDEX(출금!$A$2:$A$1048576,MATCH($S38,출금!$S$2:$S$1048576,0))) -> exchange | Q38: =IF(ISERROR(INDEX(출금!$B$2:$B$1048576,MATCH($S38,출금!$S$2:$S$1048576,0)))=TRUE, "", INDEX(출금!$B$2:$B$1048576,MATCH($S38,출금!$S$2:$S$1048576,0))) -> Binance | R38: =IF(ISERROR(INDEX(출금!$C$2:$C$1048576,MATCH($S38,출금!$S$2:$S$1048576,0)))=TRUE, "", INDEX(출금!$C$2:$C$1048576,MATCH($S38,출금!$S$2:$S$1048576,0))) -> BBRICK | S38: b510d9ab76f2346381e33d15cf47fb333afd59f6e14d79bf1f253dfaebd24366 | T38: 44543.56 | U38: =TEXT(T38,"yyyy-mm-dd") -> 2021-12-13
A39: exchange | B39: FTX | C39: BBRICK | D39: Bithumb | E39: 7 | F39: BUSD | G39: =IF(INDEX(지갑!$H:$H,MATCH(A39&B39&C39&D39&E39&F39&H39,지갑!$K:$K,0))=0, "",INDEX(지갑!$H:$H,MATCH(A39&B39&C39&D39&E39&F39&H39,지갑!$K:$K,0))) -> #N/A | I39: FTX | J39: BBRICK | K39: BUSD | L39: BSC | M39: 3000000.6 | N39: 0x8f27fa136ff4da1796368380019029d81d12d06d | O39: =IF(ISERROR(INDEX(출금!$H$2:$H$1048576,MATCH($S39,출금!$S$2:$S$1048576,0)))=TRUE, "", INDEX(출금!$H$2:$H$1048576,MATCH($S39,출금!$S$2:$S$1048576,0))&"") | P39: =IF(ISERROR(INDEX(출금!$A$2:$A$1048576,MATCH($S39,출금!$S$2:$S$1048576,0)))=TRUE, "", INDEX(출금!$A$2:$A$1048576,MATCH($S39,출금!$S$2:$S$1048576,0))) | Q39: =IF(ISERROR(INDEX(출금!$B$2:$B$1048576,MATCH($S39,출금!$S$2:$S$1048576,0)))=TRUE, "", INDEX(출금!$B$2:$B$1048576,MATCH($S39,출금!$S$2:$S$1048576,0))) | R39: =IF(ISERROR(INDEX(출금!$C$2:$C$1048576,MATCH($S39,출금!$S$2:$S$1048576,0)))=TRUE, "", INDEX(출금!$C$2:$C$1048576,MATCH($S39,출금!$S$2:$S$1048576,0))) | S39: 0xa1cb6e9698097b30e8144569ada2cbf251c56002e1282d27b4938844b631da0c | T39: 44538.887 | U39: =TEXT(T39,"yyyy-mm-dd") -> 2021-12-08
A40: exchange | B40: FTX | C40: BBRICK | D40: Bithumb | E40: 7 | F40: USD | G40: =IF(INDEX(지갑!$H:$H,MATCH(A40&B40&C40&D40&E40&F40&H40,지갑!$K:$K,0))=0, "",INDEX(지갑!$H:$H,MATCH(A40&B40&C40&D40&E40&F40&H40,지갑!$K:$K,0))) -> #N/A | I40: FTX | J40: BBRICK | K40: USD | M40: 42665.646 | N40: =IF(ISERROR(INDEX(출금!$G$2:$G$1048576,MATCH($S40,출금!$S$2:$S$1048576,0)))=TRUE, "", INDEX(출금!$G$2:$G$1048576,MATCH($S40,출금!$S$2:$S$1048576,0))&"") | O40: =IF(ISERROR(INDEX(출금!$H$2:$H$1048576,MATCH($S40,출금!$S$2:$S$1048576,0)))=TRUE, "", INDEX(출금!$H$2:$H$1048576,MATCH($S40,출금!$S$2:$S$1048576,0))&"") | P40: =IF(ISERROR(INDEX(출금!$A$2:$A$1048576,MATCH($S40,출금!$S$2:$S$1048576,0)))=TRUE, "", INDEX(출금!$A$2:$A$1048576,MATCH($S40,출금!$S$2:$S$1048576,0))) | Q40: =IF(ISERROR(INDEX(출금!$B$2:$B$1048576,MATCH($S40,출금!$S$2:$S$1048576,0)))=TRUE, "", INDEX(출금!$B$2:$B$1048576,MATCH($S40,출금!$S$2:$S$1048576,0))) | R40: =IF(ISERROR(INDEX(출금!$C$2:$C$1048576,MATCH($S40,출금!$S$2:$S$1048576,0)))=TRUE, "", INDEX(출금!$C$2:$C$1048576,MATCH($S40,출금!$S$2:$S$1048576,0))) | T40: 44538.48 | U40: =TEXT(T40,"yyyy-mm-dd") -> 2021-12-08
...

Sheet 출금
A1: account type | B1: name | C1: ownership | D1: subname | E1: api id | F1: coin | G1: address | H1: tag | I1: from | J1: Withdrawal_ownership | K1: Withdrawal_coin | L1: network | M1: quantity | N1: to | O1: to_tag | P1: to_account type | Q1: to_name | R1: to_ownership | S1: txid | T1: time | U1: Date
A2: exchange | B2: Binance | C2: 용범 | D2: Main | E2: 2 | F2: =K2 -> XLM | G2: =IF(INDEX(지갑!$H:$H,MATCH(A2&B2&C2&D2&E2&F2&H2,지갑!$K:$K,0))=0, "",INDEX(지갑!$H:$H,MATCH(A2&B2&C2&D2&E2&F2&H2,지갑!$K:$K,0))) -> GAHK7EEG2WWHVKDNT4CEQFZGKF2LGDSW2IVM4S5DP42RBW3K6BTODB4A | H2: 503825579 | I2: binance | J2: 용범 | K2: XLM | L2: XLM | M2: 60021.98 | N2: GAJWYT5AIFS6LRUIDXGII4THBSW6DI3WLTULCDK63QN43L7DTSNENUNS | O2: bc6bdca3b4b911ec | P2: =IF(ISBLANK(N2)=FALSE,IF(ISERROR(INDEX(지갑!$B$2:$B$1048576,MATCH($N2&O2,지갑!$J$2:$J$1048576,0))) = TRUE, "", INDEX(지갑!$B$2:$B$1048576,MATCH($N2&O2,지갑!$J$2:$J$1048576,0))),"") -> exchange | Q2: =IF(ISBLANK(N2)=FALSE,IF(ISERROR(INDEX(지갑!$C$2:$C$1048576,MATCH($N2&O2,지갑!$J$2:$J$1048576,0))) = TRUE, "", INDEX(지갑!$C$2:$C$1048576,MATCH($N2&O2,지갑!$J$2:$J$1048576,0))),"") -> GDAC | R2: =IF(ISBLANK(N2)=FALSE,IF(ISERROR(INDEX(지갑!$D$2:$D$1048576,MATCH($N2&O2,지갑!$J$2:$J$1048576,0))) = TRUE, "", INDEX(지갑!$D$2:$D$1048576,MATCH($N2&O2,지갑!$J$2:$J$1048576,0))),"") -> Peertec | S2: 2aecd02c884fcccafdb00e8cb96cc79a85f03751377cbadbeee41bab90116c4f | T2: 44695.72 | U2: =TEXT(T2, "yyyy-mm-dd") -> 2022-05-14
A3: exchange | B3: =I3 -> FTX | C3: =J3 -> BBRICK | D3: B-Brick | E3: 8 | F3: ETH | G3: 0xBA7600fa3507c8f357C6206B645385D7e4723895 | I3: FTX | J3: BBRICK | K3: ETH | M3: 0.116261 | O3: 1061941801 | P3: =IF(ISBLANK(N3)=FALSE,IF(ISERROR(INDEX(지갑!$B$2:$B$1048576,MATCH($N3&O3,지갑!$J$2:$J$1048576,0))) = TRUE, "", INDEX(지갑!$B$2:$B$1048576,MATCH($N3&O3,지갑!$J$2:$J$1048576,0))),"") | Q3: =IF(ISBLANK(N3)=FALSE,IF(ISERROR(INDEX(지갑!$C$2:$C$1048576,MATCH($N3&O3,지갑!$J$2:$J$1048576,0))) = TRUE, "", INDEX(지갑!$C$2:$C$1048576,MATCH($N3&O3,지갑!$J$2:$J$1048576,0))),"") | R3: =IF(ISBLANK(N3)=FALSE,IF(ISERROR(INDEX(지갑!$D$2:$D$1048576,MATCH($N3&O3,지갑!$J$2:$J$1048576,0))) = TRUE, "", INDEX(지갑!$D$2:$D$1048576,MATCH($N3&O3,지갑!$J$2:$J$1048576,0))),"") | T3: 44650.008 | U3: =TEXT(T3, "yyyy-mm-dd") -> 2022-03-30
