Workbook

Sheet 출금_피벗
B1: 출금
A3: account type | B3: (모두)
A4: Date | B4: 2021-11-23
A5: ownership | B5: (모두)
A7: 합계 : quantity | B7: 열 레이블
B8: 미확인 | C8: 미확인 요약 | D8: Peertec | E8: Peertec 요약 | F8: 총합계
A9: 행 레이블 | B9: Coinone | D9: FTX
A10: ETH | D10: 563.013 | E10: 563.013 | F10: 563.013
A11: 44523.542 | D11: 563.013 | E11: 563.013 | F11: 563.013
A12: Binance | D12: 563.013 | E12: 563.013 | F12: 563.013
A13: Main | D13: 563.013 | E13: 563.013 | F13: 563.013
A14: XRP | B14: 45293.5 | C14: 45293.5 | F14: 45293.5
A15: 44523.941 | B15: 22576.75 | C15: 22576.75 | F15: 22576.75
A16: Binance | B16: 22576.75 | C16: 22576.75 | F16: 22576.75
A17: Main | B17: 22576.75 | C17: 22576.75 | F17: 22576.75
A18: 44523.884 | B18: 22716.75 | C18: 22716.75 | F18: 22716.75
A19: Binance | B19: 22716.75 | C19: 22716.75 | F19: 22716.75
A20: Main | B20: 22716.75 | C20: 22716.75 | F20: 22716.75
A21: 총합계 | B21: 45293.5 | C21: 45293.5 | D21: 563.013 | E21: 563.013 | F21: 45856.513

Sheet 입금_피벗
B1: 입금
A2: ownership | B2: (모두)
A3: account type | B3: (모두)
A4: Date | B4: 2022-03-18
A5: Deposit_coin | B5: (다중 항목)
A7: 행 레이블 | B7: 합계 : quantity
A8: 44638.428 | B8: 3.254097
A9: FTX | B9: 3.254097
A10: Main_Peertec | B10: 3.254097
A11: 44638.512 | B11: 77.7
A12: Binance | B12: 77.7
A13: Main | B13: 77.7
A14: 총합계 | B14: 80.954097

Sheet 지갑
A1: idx | B1: account type | C1: name | D1: ownership | E1: subname | F1: api id | G1: coin | H1: address | I1: tag | J1: Prefix
A2: 1 | B2: exchange | C2: FTX | D2: Peertec | E2: Main_Peertec | F2: 10003 | G2: BTC | H2: 337ne45ueXx2iAR1gNAqxnwsCGuLquCLnh | J2: 337ne45ueXx2iAR1gNAqxnwsCGuLquCLnh | K2: exchangeFTXPeertecMain_Peertec10003BTC
A3: 1 | B3: exchange | C3: FTX | D3: Peertec | E3: Main_Peertec | F3: 10003 | G3: XRP | H3: rPFXvVo2fYXVPdV9gCHQouHsMgMhQ2aUwM | I3: 3680179910 | J3: rPFXvVo2fYXVPdV9gCHQouHsMgMhQ2aUwM3680179910 | K3: exchangeFTXPeertecMain_Peertec10003XRP3680179910
A4: 1 | B4: exchange | C4: FTX | D4: Peertec | E4: Main_Peertec | F4: 10003 | G4: ETH | H4: 0xaB4Bfe506a3Cb36ADDf97678293bD429B9951726 | J4: 0xaB4Bfe506a3Cb36ADDf97678293bD429B9951726 | K4: exchangeFTXPeertecMain_Peertec10003ETH
A5: 1 | B5: exchange | C5: FTX | D5: Peertec | E5: Main_Peertec | F5: 10003 | G5: USDC | H5: 0x8E59558B73A92572834169Dc0096df9E42168B57 | J5: 0x8E59558B73A92572834169Dc0096df9E42168B57 | K5: exchangeFTXPeertecMain_Peertec10003USDC
A6: 1 | B6: exchange | C6: FTX | D6: Peertec | E6: Main_Peertec | F6: 10003 | G6: USDT | H6: 0x8f27fa136ff4da1796368380019029d81d12d06d | J6: 0x8f27fa136ff4da1796368380019029d81d12d06d | K6: exchangeFTXPeertecMain_Peertec10003USDT
A7: 1 | B7: exchange | C7: FTX | D7: Peertec | E7: Main_Peertec | F7: 10003 | G7: LUNA | H7: terra1luagdjcr9c9yvp3ak4d7chjm5gldcmgln5rku5 | I7: 823031602 | J7: terra1luagdjcr9c9yvp3ak4d7chjm5gldcmgln5rku5823031602 | K7: exchangeFTXPeertecMain_Peertec10003LUNA823031602
A8: 1 | B8: exchange | C8: FTX | D8: Peertec | E8: Main_Peertec | F8: 10003 | G8: UST | H8: terra1luagdjcr9c9yvp3ak4d7chjm5gldcmgln5rku5 | I8: 823031602 | J8: terra1luagdjcr9c9yvp3ak4d7chjm5gldcmgln5rku5823031602 | K8: exchangeFTXPeertecMain_Peertec10003UST823031602
A9: 1 | B9: exchange | C9: FTX | D9: Peertec | E9: Main_Peertec | F9: 10003 | G9: ATOM | H9: cosmos1kvyevlmp0gfd7f9qdnkq98tc59p2mg2smppwn7 | I9: 3529325778 | J9: cosmos1kvyevlmp0gfd7f9qdnkq98tc59p2mg2smppwn73529325778 | K9: exchangeFTXPeertecMain_Peertec10003ATOM3529325778
A10: 1 | B10: exchange | C10: FTX | D10: Peertec | E10: Main_Peertec | F10: 10003 | G10: MATIC | K10: exchangeFTXPeertecMain_Peertec10003MATIC
A11: 1 | B11: exchange | C11: FTX | D11: Peertec | E11: Main_Peertec | F11: 10003 | G11: NEAR | K11: exchangeFTXPeertecMain_Peertec10003NEAR
A12: 1 | B12: exchange | C12: FTX | D12: Peertec | E12: Main_Peertec | F12: 10003 | G12: TRX | K12: exchangeFTXPeertecMain_Peertec10003TRX
A13: 1 | B13: exchange | C13: FTX | D13: Peertec | E13: Main_Peertec | F13: 10003 | G13: BCH | H13: bitcoincash:qrl59ue7seauw2lsj370zu70gq04zwsh5unkfg6scm | J13: bitcoincash:qrl59ue7seauw2lsj370zu70gq04zwsh5unkfg6scm | K13: exchangeFTXPeertecMain_Peertec10003BCH
A14: 1 | B14: exchange | C14: FTX | D14: Peertec | E14: Main_Peertec | F14: 10003 | G14: BNB | K14: exchangeFTXPeertecMain_Peertec10003BNB
B15: exchange | C15: FTX | D15: Peertec | E15: Main_Peertec | F15: 10003 | G15: BUSD | K15: exchangeFTXPeertecMain_Peertec10003BUSD
A16: 1 | B16: exchange | C16: FTX | D16: Peertec | E16: Main_Peertec | F16: 10003 | G16: SOL | H16: DqF4jpup3cLNkMhVxCxNqKnxxqFuVNf4zfeAnvpqdbfr | J16: DqF4jpup3cLNkMhVxCxNqKnxxqFuVNf4zfeAnvpqdbfr | K16: exchangeFTXPeertecMain_Peertec10003SOL
A17: 1 | B17: exchange | C17: FTX | D17: Peertec | E17: Main_Peertec | F17: 10003 | G17: LTC | K17: exchangeFTXPeertecMain_Peertec10003LTC
A18: 2 | B18: exchange | C18: FTX | D18: BBRICK | E18: Main_Bbrick | F18: 10025 | G18: BTC | H18: 3H9GcbHrica8tDjBgkByHKNbwpcdTapLoK | J18: 3H9GcbHrica8tDjBgkByHKNbwpcdTapLoK | K18: exchangeFTXBBRICKMain_Bbrick10025BTC
A19: 2 | B19: exchange | C19: FTX | D19: BBRICK | E19: Main_Bbrick | F19: 10025 | G19: XRP | H19: rPFXvVo2fYXVPdV9gCHQouHsMgMhQ2aUwM | I19: 3396311572 | J19: rPFXvVo2fYXVPdV9gCHQouHsMgMhQ2aUwM3396311572 | K19: exchangeFTXBBRICKMain_Bbrick10025XRP3396311572
A20: 2 | B20: exchange | C20: FTX | D20: BBRICK | E20: Main_Bbrick | F20: 10025 | G20: ETH | H20: 0xd16eEBDb4F8804b66AB4b2c536917154d9a47E82 | J20: 0xd16eEBDb4F8804b66AB4b2c536917154d9a47E82 | K20: exchangeFTXBBRICKMain_Bbrick10025ETH
A21: 2 | B21: exchange | C21: FTX | D21: BBRICK | E21: Main_Bbrick | F21: 10025 | G21: USDC | H21: 0xA341107b28740ee5a003BA3960448fD14174a026 | J21: 0xA341107b28740ee5a003BA3960448fD14174a026 | K21: exchangeFTXBBRICKMain_Bbrick10025USDC
A22: 2 | B22: exchange | C22: FTX | D22: BBRICK | E22: Main_Bbrick | F22: 10025 | G22: USDT | H22: 0xA341107b28740ee5a003BA3960448fD14174a026 | J22: 0xA341107b28740ee5a003BA3960448fD14174a026 | K22: exchangeFTXBBRICKMain_Bbrick10025USDT
A23: 2 | B23: exchange | C23: FTX | D23: BBRICK | E23: Main_Bbrick | F23: 10025 | G23: LUNA | H23: terra1luagdjcr9c9yvp3ak4d7chjm5gldcmgln5rku5 | I23: 1273090217 | J23: terra1luagdjcr9c9yvp3ak4d7chjm5gldcmgln5rku51273090217 | K23: exchangeFTXBBRICKMain_Bbrick10025LUNA1273090217
A24: 2 | B24: exchange | C24: FTX | D24: BBRICK | E24: Main_Bbrick | F24: 10025 | G24: UST | H24: terra1luagdjcr9c9yvp3ak4d7chjm5gldcmgln5rku5 | I24: 1273090217 | J24: terra1luagdjcr9c9yvp3ak4d7chjm5gldcmgln5rku51273090217 | K24: exchangeFTXBBRICKMain_Bbrick10025UST1273090217
A25: 2 | B25: exchange | C25: FTX | D25: BBRICK | E25: Main_Bbrick | F25: 10025 | G25: BNB | K25: exchangeFTXBBRICKMain_Bbrick10025BNB
A26: 2 | B26: exchange | C26: FTX | D26: BBRICK | E26: Main_Bbrick | F26: 10025 | G26: DAI | K26: exchangeFTXBBRICKMain_Bbrick10025DAI
A27: 2 | B27: exchange | C27: FTX | D27: BBRICK | E27: Main_Bbrick | F27: 10025 | G27: LTC | K27: exchangeFTXBBRICKMain_Bbrick10025LTC
A28: 2 | B28: exchange | C28: FTX | D28: BBRICK | E28: Main_Bbrick | F28: 10025 | G28: SOL | H28: Ge2iS3fXCNM3LwzECBAoHba6JgubMwB9R7NGmvSu6MuG | J28: Ge2iS3fXCNM3LwzECBAoHba6JgubMwB9R7NGmvSu6MuG | K28: exchangeFTXBBRICKMain_Bbrick10025SOL
A29: 2 | B29: exchange | C29: FTX | D29: BBRICK | E29: Main_Bbrick | F29: 10025 | G29: USD | K29: exchangeFTXBBRICKMain_Bbrick10025USD
A30: 2 | B30: exchange | C30: FTX | D30: BBRICK | E30: Main_Bbrick | F30: 10025 | G30: WBTC | K30: exchangeFTXBBRICKMain_Bbrick10025WBTC
A31: 3 | B31: exchange | C31: FTX | D31: BBRICK | E31: Bithumb_ETH | F31: 1 | G31: BTC | H31: 35JMNYtbvEjth4TLgiPDbhswho65ydNhVF | J31: 35JMNYtbvEjth4TLgiPDbhswho65ydNhVF | K31: exchangeFTXBBRICKBithumb_ETH1BTC
A32: 3 | B32: exchange | C32: FTX | D32: BBRICK | E32: Bithumb_ETH | F32: 1 | G32: XRP | H32: rPFXvVo2fYXVPdV9gCHQouHsMgMhQ2aUwM | I32: 1824918435 | J32: rPFXvVo2fYXVPdV9gCHQouHsMgMhQ2aUwM1824918435 | K32: exchangeFTXBBRICKBithumb_ETH1XRP1824918435
A33: 3 | B33: exchange | C33: FTX | D33: BBRICK | E33: Bithumb_ETH | F33: 1 | G33: ETH | H33: 0xAe45aBf4685B0A0a81664094896CB1e378710168 | J33: 0xAe45aBf4685B0A0a81664094896CB1e378710168 | K33: exchangeFTXBBRICKBithumb_ETH1ETH
A34: 3 | B34: exchange | C34: FTX | D34: BBRICK | E34: Bithumb_ETH | F34: 1 | G34: USDC | H34: 0x072f87370eFF242A1eD79907dD990846Ad934Bd8 | J34: 0x072f87370eFF242A1eD79907dD990846Ad934Bd8 | K34: exchangeFTXBBRICKBithumb_ETH1USDC
A35: 3 | B35: exchange | C35: FTX | D35: BBRICK | E35: Bithumb_ETH | F35: 1 | G35: USDT | H35: 0x072f87370eFF242A1eD79907dD990846Ad934Bd8 | J35: 0x072f87370eFF242A1eD79907dD990846Ad934Bd8 | K35: exchangeFTXBBRICKBithumb_ETH1USDT
A36: 3 | B36: exchange | C36: FTX | D36: BBRICK | E36: Bithumb_ETH | F36: 1 | G36: LUNA | H36: terra1luagdjcr9c9yvp3ak4d7chjm5gldcmgln5rku5 | I36: 614830254 | J36: terra1luagdjcr9c9yvp3ak4d7chjm5gldcmgln5rku5614830254 | K36: exchangeFTXBBRICKBithumb_ETH1LUNA614830254
B37: exchange | C37: FTX | D37: BBRICK | E37: Bithumb_ETH | F37: 1 | G37: TRX | H37: TQ4oJx8GtPV34vBwxErGKj2n6rmhPycYni | J37: TQ4oJx8GtPV34vBwxErGKj2n6rmhPycYni | K37: exchangeFTXBBRICKBithumb_ETH1TRX
A38: 3 | B38: exchange | C38: FTX | D38: BBRICK | E38: Bithumb_ETH | F38: 1 | G38: UST | H38: terra1luagdjcr9c9yvp3ak4d7chjm5gldcmgln5rku5 | I38: 614830254 | J38: terra1luagdjcr9c9yvp3ak4d7chjm5gldcmgln5rku5614830254 | K38: exchangeFTXBBRICKBithumb_ETH1UST614830254
A39: 4 | B39: exchange | C39: FTX | D39: BBRICK | E39: B-Brick | F39: 8 | G39: BTC | H39: 39wUrg2Sd1UG8Gey19faN4YQRPYEDpb48E | J39: 39wUrg2Sd1UG8Gey19faN4YQRPYEDpb48E | K39: exchangeFTXBBRICKB-Brick8BTC
A40: 4 | B40: exchange | C40: FTX | D40: BBRICK | E40: B-Brick | F40: 8 | G40: XRP | H40: rPFXvVo2fYXVPdV9gCHQouHsMgMhQ2aUwM | I40: 1464472549 | J40: rPFXvVo2fYXVPdV9gCHQouHsMgMhQ2aUwM1464472549 | K40: exchangeFTXBBRICKB-Brick8XRP1464472549
...

Sheet 입금
A1: account type | B1: name | C1: ownership | D1: subname | E1: api id | F1: coin | G1: address | H1: tag | I1: to | J1: Deposit_Ownership | K1: Deposit_coin | L1: network | M1: quantity | N1: from | O1: from_tag | P1: from_account type | Q1: from_name | R1: from_ownership | S1: txid | T1: time | U1: Date
A2: exchange | B2: FTX | C2: BBRICK | D2: B-Brick | E2: 8 | F2: USDC | G2: 0xAa149A5172c5f27a8a259001AD3d62B2166Ae851 | I2: FTX | J2: BBRICK | K2: USDC | L2: ERC20 | M2: 20637800 | N2: 0x44b68b196148e426402b3e9ab3be974176ad32c0 | S2: 0xca901c2b87fffea7cceb8701e6352a0b500d6738700e9ee0076128ad667fbce4 | T2: 44631.748 | U2: 2022-03-11
A3: exchange | B3: FTX | C3: BBRICK | D3: B-Brick | E3: 8 | F3: USDC | G3: 0xAa149A5172c5f27a8a259001AD3d62B2166Ae851 | I3: FTX | J3: BBRICK | K3: USDC | L3: ERC20 | M3: 8491319 | N3: 0x44b68b196148e426402b3e9ab3be974176ad32c0 | S3: 0xf2f1e89f40e73e228cea3db35b841552f9494f46333387fb72501370a5532a93 | T3: 44628.538 | U3: 2022-03-08
A4: exchange | B4: FTX | C4: BBRICK | D4: B-Brick | E4: 8 | F4: USDC | G4: 0xAa149A5172c5f27a8a259001AD3d62B2166Ae851 | I4: FTX | J4: BBRICK | K4: USDC | L4: ERC20 | M4: 10 | N4: 0x44b68b196148e426402b3e9ab3be974176ad32c0 | S4: 0x71ebc28929e3f55b839f7a3a40eed3aaa891bacedccd143e57e1e8b2a1fb4ffd | T4: 44628.451 | U4: 2022-03-08
A5: exchange | B5: Huobi | C5: Peertec | F5: ETH | G5: 0xdb245cf0aec8bf5d4b3002d00f3e701e80ba380a | I5: Huobi | J5: Peertec | K5: ETH | L5: ETH | M5: 249.99 | N5: 0x97122ddca38c29b7653d52b07998d06a7128fa0b | S5: af3a9795b83dd46101b341f7c10046fec83b22e3e84cf39d2d64c7ae6356c572 | T5: 44232.773 | U5: 2021-02-05
A6: exchange | B6: FTX | C6: BBRICK | D6: B-Brick | E6: 8 | F6: ETH | G6: 0xBA7600fa3507c8f357C6206B645385D7e4723895 | I6: FTX | J6: BBRICK | K6: ETH | L6: ETH | M6: 2390.1163 | N6: 0xc168062c9c958e01914c7e3885537541dbb9ed08 | S6: 0xdd1194b1aa66f21200313ac0fbc08bfab4344825491ea0b8e327e3edd79aaf9d | T6: 44614.602 | U6: 2022-02-22
A7: exchange | B7: FTX | C7: BBRICK | D7: B-Brick | E7: 8 | F7: ETH | G7: 0xBA7600fa3507c8f357C6206B645385D7e4723895 | I7: FTX | J7: BBRICK | K7: ETH | L7: ETH | M7: 4200 | N7: 0xafadc4302f07e9460eb4c31ec741c0f3e308ff3a | S7: 0xf2fa7849093bc059c5b015bf23d6aa75b68c1cc7cc57a95d939c86694ce41640 | T7: 44614.581 | U7: 2022-02-22
A8: exchange | B8: FTX | C8: BBRICK | D8: B-Brick | E8: 8 | F8: USD | G8: #N/A | I8: FTX | J8: BBRICK | K8: USD | M8: 1110350.2 | T8: 44579.426 | U8: 2022-01-18
A9: exchange | B9: FTX | C9: BBRICK | D9: B-Brick | E9: 8 | F9: USD | G9: #N/A | I9: FTX | J9: BBRICK | K9: USD | M9: 110350.18 | T9: 44579.426 | U9: 2022-01-18
A10: exchange | B10: FTX | C10: BBRICK | D10: B-Brick | E10: 8 | F10: SOL | G10: 4WALSVwxUyuXkxFqSwcweEgh2ddYjYoaFw3yUw3GMDPK | I10: FTX | J10: BBRICK | K10: SOL | M10: 1497.5786 | T10: 44579.426 | U10: 2022-01-18
A11: exchange | B11: FTX | C11: BBRICK | D11: B-Brick | E11: 8 | F11: USD | G11: #N/A | I11: FTX | J11: BBRICK | K11: USD | M11: 1497.5786 | T11: 44579.426 | U11: 2022-01-18
A12: exchange | B12: FTX | C12: BBRICK | D12: B-Brick | E12: 8 | F12: SOL | G12: 4WALSVwxUyuXkxFqSwcweEgh2ddYjYoaFw3yUw3GMDPK | I12: FTX | J12: BBRICK | K12: SOL | M12: 1497.5786 | T12: 44578.41 | U12: 2022-01-17
A13: exchange | B13: FTX | C13: BBRICK | D13: B-Brick | E13: 8 | F13: USD | G13: #N/A | I13: FTX | J13: BBRICK | K13: USD | M13: 1512134 | T13: 44578.404 | U13: 2022-01-17
A14: exchange | B14: FTX | C14: BBRICK | D14: B-Brick | E14: 8 | F14: BUSD | G14: #N/A | I14: FTX | J14: BBRICK | K14: BUSD | L14: BSC | M14: 1463218 | N14: 0xa3479d004c339ab1bc8a5873b5657e7aecd6af461f3b01bea3a572073b290689 (Binance: Hot Wallet 6) | P14: exchange | Q14: Binance | R14: BBRICK | S14: 0xa3479d004c339ab1bc8a5873b5657e7aecd6af461f3b01bea3a572073b290689 | T14: 44561.563 | U14: 2021-12-31
A15: exchange | B15: OKEX | C15: Peertec | F15: KLAY | G15: 0x5006bc0d4fa0117e93d21aa663969fc6703a4319 | I15: OKEX | J15: Peertec | K15: KLAY | L15: KLAY | M15: 7901.1188 | N15: 0x980e9dfeaa8ea715e97827bb770fac8b97090ef1 | S15: 0x1149ea5ef99a22a9d4d04c65e21daf9e25d35dbaf2098171774817032b1914b7 | T15: 44646.193 | U15: 2022-03-26
A16: exchange | B16: FTX | C16: BBRICK | D16: B-Brick | E16: 8 | F16: SOL | G16: 4WALSVwxUyuXkxFqSwcweEgh2ddYjYoaFw3yUw3GMDPK | I16: FTX | J16: BBRICK | K16: SOL | M16: 1497.5786 | T16: 44561.508 | U16: 2021-12-31
A17: exchange | B17: FTX | C17: BBRICK | D17: B-Brick | E17: 8 | F17: BTC | G17: 39wUrg2Sd1UG8Gey19faN4YQRPYEDpb48E | I17: FTX | J17: BBRICK | K17: BTC | M17: 7.3130319 | T17: 44477.608 | U17: 2021-10-08
A18: exchange | B18: OKEX | C18: Peertec | F18: USDT | G18: 0x5006bc0d4fa0117e93d21aa663969fc6703a4319 | I18: OKEX | J18: Peertec | K18: USDT | L18: TRON | M18: 100 | N18: 0xA341107b28740ee5a003BA3960448fD14174a026 | P18: exchange | Q18: FTX | R18: BBRICK | S18: 2e38fa3e38e04b21edba9a15a00c1bcc18ba93ca3984463d0ce565ff056ff80f | T18: 44647.91 | U18: 2022-03-27
A19: Wallet | B19: Terra | C19: BBRICK | D19: 비브릭용_Terra_wallet | G19: terra174evzq0tnd0uvzkkrvg08n9geqpcsvdrychcm8 | I19: Terra | J19: BBRICK | K19: Luna | L19: TERRA | M19: 9.98 | N19: terra1ncjg4a59x2pgvqy9qjyqprlj8lrwshm0wleht5 | O19: 102585224 | P19: exchange | Q19: Binance | R19: BBRICK | S19: B1CA82D9B8741FBBE0C9274A99FBDC8B2A8363C2AEA508C6AB43C7175DD6CA66 | T19: 44478.494 | U19: 2021-10-09
A20: exchange | B20: OKEX | C20: Peertec | F20: KLAY | G20: 0x5006bc0d4fa0117e93d21aa663969fc6703a4319 | I20: OKEX | J20: Peertec | K20: KLAY | L20: KLAY | M20: 40.431743 | N20: 0x980e9dfeaa8ea715e97827bb770fac8b97090ef1 | S20: 0x3a52ff0b68ef3e5e0b32ebf4649cc2d9424ae155b8071ccd09427d126a1e140f | T20: 44648.347 | U20: 2022-03-28
A21: exchange | B21: FTX | C21: BBRICK | D21: B-Brick | E21: 8 | F21: USD | G21: #N/A | I21: FTX | J21: BBRICK | K21: USD | M21: 200000 | T21: 44175.379 | U21: 2020-12-10
A22: exchange | B22: FTX | C22: BBRICK | D22: B-Brick | E22: 8 | F22: USD | G22: #N/A | I22: FTX | J22: BBRICK | K22: USD | M22: 10000 | T22: 44168.476 | U22: 2020-12-03
A23: exchange | B23: OKEX | C23: Peertec | F23: ETC | G23: 0x4972a657d735e8ff5c2cfd2a7a5299100091f900? | I23: OKEX | J23: Peertec | K23: ETC | L23: ETC | M23: 55.838991 | S23: 0x1af0c1f70aa0aab493c51111d00bb42f22e876932807c34f73162d02ea4d4281 | T23: 44650.403 | U23: 2022-03-30
A24: exchange | B24: FTX | C24: BBRICK | D24: Bithumb | E24: 7 | F24: BNB | G24: #N/A | I24: FTX | J24: BBRICK | K24: BNB | M24: 100 | T24: 44568.915 | U24: 2022-01-07
A25: exchange | B25: OKEX | C25: Peertec | F25: KLAY | G25: 0x5006bc0d4fa0117e93d21aa663969fc6703a4319 | I25: OKEX | J25: Peertec | K25: KLAY | L25: KLAY | M25: 3336.2992 | S25: 0x24002ac340feb36276a502abea542d98a9609ebafe0e24950159e0ac6cc8c14c | T25: 44651.605 | U25: 2022-03-31
A26: exchange | B26: Huobi | C26: Peertec | F26: BTC | G26: 1MdatewJkKfSptYBaJvgEBFYCEbiCkELVt | I26: Huobi | J26: Peertec | K26: BTC | L26: BTC | M26: 9.999 | S26: c5bf3d207c6d5f31760dcf12de54d28fd2a0d624c102b7b73c83b61bfaff2857 | T26: 44232.79 | U26: 2021-02-05
A27: exchange | B27: FTX | C27: BBRICK | D27: Bithumb | E27: 7 | F27: USDT | G27: 0xCe17482d83FD53E2A921186Bd6ddd412610F7A1f | I27: FTX | J27: BBRICK | K27: USDT | M27: 50000 | T27: 44568.915 | U27: 2022-01-07
A28: exchange | B28: OKEX | C28: Peertec | F28: KLAY | G28: 0x5006bc0d4fa0117e93d21aa663969fc6703a4319 | I28: OKEX | J28: Peertec | K28: KLAY | L28: KLAY | M28: 368.88561 | S28: 0x6a685666a848cd04e240a06ea1777d5e080ebb5842dee373b93bf3b474c12a73 | T28: 44652.405 | U28: 2022-04-01
A29: Wallet | B29: Terra | C29: BBRICK | D29: 비브릭용_Terra_wallet | G29: terra174evzq0tnd0uvzkkrvg08n9geqpcsvdrychcm8 | I29: Terra | J29: BBRICK | K29: UST | L29: TERRA | M29: 41.79 | S29: 35A121273CA223DB68B0F4FE17B1D5F24C2F8E2726AD679E8C405072437CFF2E | T29: 44479.446 | U29: 2021-10-10
A30: exchange | B30: FTX | C30: BBRICK | D30: Bithumb | E30: 7 | F30: ETH | G30: 0x87b88FB60b6429DB66ADd58aB6C909A1C715E346 | I30: FTX | J30: BBRICK | K30: ETH | M30: 10 | T30: 44568.914 | U30: 2022-01-07
A31: exchange | B31: FTX | C31: BBRICK | D31: Bithumb | E31: 7 | F31: BTC | G31: 3LLRS688CkBg71m4qvEffbHh9sMQZfH5or | I31: FTX | J31: BBRICK | K31: BTC | L31: BTC | M31: 86.706938 | N31: 1MdatewJkKfSptYBaJvgEBFYCEbiCkELVt | P31: exchange | Q31: Huobi | R31: Peertec | S31: 637d7d46d77fb54bd69a8ba6da94ef3b1c68466c0b29793fb8d50975ee7d92ef | T31: 44565.849 | U31: 2022-01-04
A32: exchange | B32: FTX | C32: BBRICK | D32: Bithumb | E32: 7 | F32: BTC | G32: 3LLRS688CkBg71m4qvEffbHh9sMQZfH5or | I32: FTX | J32: BBRICK | K32: BTC | L32: BTC | M32: 287.12601 | S32: b4198e30f515922967c0a9df9f6b0b14567440424987a3755d674a771dd98cd9 | T32: 44564.588 | U32: 2022-01-03
A33: exchange | B33: FTX | C33: BBRICK | D33: Bithumb | E33: 7 | F33: SOL | G33: HFaX33KAtC9knovpb1xsMXfV971D8L4Qhf66XzozYGww | I33: FTX | J33: BBRICK | K33: SOL | L33: SOL | M33: 1392.35 | N33: SUZXwKfyPi8U4nMJNvT6b7WgDkaKmHvfVT9uE3yZYjx | P33: exchange | Q33: Binance | R33: BBRICK | S33: KP5Gtd4xFrbTZjBicdcA7XJKSJmJK3Sn6UuaSqEGrG9owYofemYFMKURxyF4TQ4N1Rj2GaCZ5x7Kmxerd3uTyvL | T33: 44561.458 | U33: 2021-12-31
A34: exchange | B34: FTX | C34: BBRICK | D34: Bithumb | E34: 7 | F34: ETH | G34: 0x87b88FB60b6429DB66ADd58aB6C909A1C715E346 | I34: FTX | J34: BBRICK | K34: ETH | L34: ETH | M34: 4452.9275 | N34: 0xdc5432c573a1d4874d305a5cd7e62aed2b0bc522 | S34: 0x9821f31820059106963ee5176058b34cc215dcf5626ee55e071459daa163edb4 | T34: 44553.44 | U34: 2021-12-23
A35: exchange | B35: FTX | C35: BBRICK | D35: Bithumb | E35: 7 | F35: SOL | G35: HFaX33KAtC9knovpb1xsMXfV971D8L4Qhf66XzozYGww | I35: FTX | J35: BBRICK | K35: SOL | L35: SOL | M35: 99.95 | S35: 55PepaBZVkNKhxr7J5v6asCQyZx4H3HDhwxnbG13uGb6aL7tHYjCS96dooa7hQvmBAgQqBXrmbiZS48HJsi9a9H7 | T35: 44552.626 | U35: 2021-12-22
A36: exchange | B36: FTX | C36: BBRICK | D36: Bithumb | E36: 7 | F36: USDC | G36: 0xCe17482d83FD53E2A921186Bd6ddd412610F7A1f | I36: FTX | J36: BBRICK | K36: USDC | L36: SOL | M36: 1000080.2 | N36: TJrPnAJbrzjfqKtGgQ24Yg7p4kaWg73wAT | P36: exchange | Q36: Huobi | R36: Peertec | S36: 5LSxtofmdBzu4PDm8iLjk1e581ELvLuEsubLkbB6QS76nD2FrfC5deNbsbBHmMFap2iYaCJgbNFNKNLsNtCHU65M | T36: 44544.258 | U36: 2021-12-14
A37: exchange | B37: FTX | C37: BBRICK | D37: Bithumb | E37: 7 | F37: USDC | G37: 0xCe17482d83FD53E2A921186Bd6ddd412610F7A1f | I37: FTX | J37: BBRICK | K37: USDC | L37: ERC20 | M37: 65705.852 | N37: 0x02074984dab902181b4263f52f6b5437f011b606 | S37: 0x02d0147820b62d8b8c6c88bd1d26148b213c4668b6555067860319a45f89f3e6 | T37: 44543.793 | U37: 2021-12-13
A38: exchange | B38: FTX | C38: BBRICK | D38: Bithumb | E38: 7 | F38: BTC | G38: 3LLRS688CkBg71m4qvEffbHh9sMQZfH5or | I38: FTX | J38: BBRICK | K38: BTC | L38: BTC | M38: 99.9995 | N38: 19SK9LWSXLdmwPxvjPgvUrdaPhaPS6LaNu | P38: exchange | Q38: Binance | R38: BBRICK | S38: b510d9ab76f2346381e33d15cf47fb333afd59f6e14d79bf1f253dfaebd24366 | T38: 44543.56 | U38: 2021-12-13
A39: exchange | B39: FTX | C39: BBRICK | D39: Bithumb | E39: 7 | F39: BUSD | G39: #N/A | I39: FTX | J39: BBRICK | K39: BUSD | L39: BSC | M39: 3000000.6 | N39: 0x8f27fa136ff4da1796368380019029d81d12d06d | S39: 0xa1cb6e9698097b30e8144569ada2cbf251c56002e1282d27b4938844b631da0c | T39: 44538.887 | U39: 2021-12-08
A40: exchange | B40: FTX | C40: BBRICK | D40: Bithumb | E40: 7 | F40: USD | G40: #N/A | I40: FTX | J40: BBRICK | K40: USD | M40: 42665.646 | T40: 44538.48 | U40: 2021-12-08
...

Sheet 출금
A1: account type | B1: name | C1: ownership | D1: subname | E1: api id | F1: coin | G1: address | H1: tag | I1: from | J1: Withdrawal_ownership | K1: Withdrawal_coin | L1: network | M1: quantity | N1: to | O1: to_tag | P1: to_account type | Q1: to_name | R1: to_ownership | S1: txid | T1: time | U1: Date
A2: exchange | B2: Binance | C2: 용범 | D2: Main | E2: 2 | F2: XLM | G2: GAHK7EEG2WWHVKDNT4CEQFZGKF2LGDSW2IVM4S5DP42RBW3K6BTODB4A | H2: 503825579 | I2: binance | J2: 용범 | K2: XLM | L2: XLM | M2: 60021.98 | N2: GAJWYT5AIFS6LRUIDXGII4THBSW6DI3WLTULCDK63QN43L7DTSNENUNS | O2: bc6bdca3b4b911ec | P2: exchange | Q2: GDAC | R2: Peertec | S2: 2aecd02c884fcccafdb00e8cb96cc79a85f03751377cbadbeee41bab90116c4f | T2: 44695.72 | U2: 2022-05-14
A3: exchange | B3: FTX | C3: BBRICK | D3: B-Brick | E3: 8 | F3: ETH | G3: 0xBA7600fa3507c8f357C6206B645385D7e4723895 | I3: FTX | J3: BBRICK | K3: ETH | M3: 0.116261 | O3: 1061941801 | T3: 44650.008 | U3: 2022-03-30
A4: exchange | B4: FTX | C4: BBRICK | D4: B-Brick | E4: 8 | F4: USDC | G4: 0xAa149A5172c5f27a8a259001AD3d62B2166Ae851 | I4: FTX | J4: BBRICK | K4: USDC | L4: ERC20 | M4: 20637800 | N4: 0x8F27fa136Ff4Da1796368380019029d81d12D06D | P4: exchange | Q4: FTX | R4: Peertec | S4: 0x678938cb0fd14d1d1db716011a6490ae1801842793db5c515226e9be538652cd | T4: 44631.757 | U4: 2022-03-11
A5: exchange | B5: FTX | C5: BBRICK | D5: B-Brick | E5: 8 | F5: ETH | G5: 0xBA7600fa3507c8f357C6206B645385D7e4723895 | I5: FTX | J5: BBRICK | K5: ETH | L5: ETH | M5: 6090 | N5: 0xbA85793220727e998fec66Dd8f6e68eCC8790696 | S5: 0x97352722e62785716ecb93af3b2f5734bad20241cc7478a940544ea6fa0ce010 | T5: 44631.612 | U5: 2022-03-11
A6: Wallet | B6: Terra | C6: BBRICK | D6: 지닥용_Terra_wallet | G6: terra1j4u9e5n8xu9c9jykny8uqw6lde6843qczzwd0x | I6: 지닥용 테라 지갑 | J6: BBRICK | K6: UST | L6: Terra | M6: 70 | N6: terra1luagdjcr9c9yvp3ak4d7chjm5gldcmgln5rku5 | O6: 823031602 | P6: exchange | Q6: FTX | R6: Peertec | S6: 6D166E8B5EC60C73BDF1D6A10A603205CFDC8FDD1E23C5B5520498ACDFEC962C | T6: 44695.395 | U6: 2022-05-14
A7: exchange | B7: Binance | C7: 용범 | D7: Main | E7: 2 | F7: XLM | G7: GAHK7EEG2WWHVKDNT4CEQFZGKF2LGDSW2IVM4S5DP42RBW3K6BTODB4A | H7: 503825579 | I7: binance | J7: 용범 | K7: XLM | L7: XLM | M7: 72794.98 | N7: GAHK7EEG2WWHVKDNT4CEQFZGKF2LGDSW2IVM4S5DP42RBW3K6BTODB4A | O7: 1061941801 | P7: exchange | Q7: Binance | R7: BBRICK | S7: Internal transfer 106561603995 | T7: 44695.378 | U7: 2022-05-14
A8: exchange | B8: Binance | C8: 용범 | D8: Main | E8: 2 | F8: UST | G8: terra1ncjg4a59x2pgvqy9qjyqprlj8lrwshm0wleht5 | H8: 104455866 | I8: binance | J8: 용범 | K8: UST | L8: LUNA | M8: 243954.32 | N8: terra1s7gxam60m650w29s64ckqrw902c9nshgeu3zm8 | P8: Wallet | Q8: Terra | R8: 권용진 | S8: 8D6B947C30CBA2E9756E217D8FA8F51E9588E758D9E7B654A88B5FEDDC789F3D | T8: 44686.229 | U8: 2022-05-05
A9: exchange | B9: Binance | C9: 용범 | D9: Main | E9: 2 | F9: BTC | G9: 1MoyhGNqvJj5SmrSFWgqyY5jJ7JXMrVaib | I9: binance | J9: 용범 | K9: BTC | L9: BTC | M9: 6 | N9: 374LRSWxDhVMJGYVdvawesWpuHxR6toVaG | P9: exchange | Q9: Upbit | R9: 용범 | S9: 8e94574d292f63e82bc390dfe925eaa23a967a2eab028f5013cce5be99497ef2 | T9: 44677.758 | U9: 2022-04-26
A10: exchange | B10: Binance | C10: 용범 | D10: Main | E10: 2 | F10: BTC | G10: 1MoyhGNqvJj5SmrSFWgqyY5jJ7JXMrVaib | I10: binance | J10: 용범 | K10: BTC | L10: BTC | M10: 1 | N10: 374LRSWxDhVMJGYVdvawesWpuHxR6toVaG | P10: exchange | Q10: Upbit | R10: 용범 | S10: 2701dd628bae8b6d15c73fce5061a6d2eba6343e521420a13e87acbd9dc894ed | T10: 44668.541 | U10: 2022-04-17
A11: exchange | B11: FTX | C11: BBRICK | D11: B-Brick | E11: 8 | F11: USDC | G11: 0xAa149A5172c5f27a8a259001AD3d62B2166Ae851 | I11: FTX | J11: BBRICK | K11: USDC | L11: ERC20 | M11: 8491329 | N11: 0x81251D5047F57Bb6158D39B72aE1bf92FaF26261 | P11: Wallet | Q11: Metamask | R11: Peertec | S11: 0xeb2ed09521fa37e99485f2488bebb8d33c30bf1b780141680378ca6fc56f9c26 | T11: 44628.642 | U11: 2022-03-08
A12: exchange | B12: OKEX | C12: Peertec | F12: USDT | G12: 0x5006bc0d4fa0117e93d21aa663969fc6703a4319 | I12: OKEX | J12: Peertec | K12: USDT | L12: TRON | M12: 164368.5 | N12: TKt8ayzQe4UgGrh3ezSBncjsdbMAgH7QWc | P12: exchange | Q12: Binance | R12: BBRICK | S12: 876184d5147cd304819d17a51fc18e33db0657f5599f741955b471e6c429eac0 | T12: 44694.7 | U12: 2022-05-13
A13: exchange | B13: Binance | C13: 용범 | D13: Main | E13: 2 | F13: XRP | G13: #N/A | I13: binance | J13: 용범 | K13: XRP | L13: XRP | M13: 79999.5 | N13: raQwCVAJVqjrVm1Nj5SFRcX8i22BhdC9WA | O13: 2928323236 | P13: exchange | Q13: Upbit | R13: 용범 | S13: 5E04019A261D0EE0C987D175FBF66AA502368752C525B17BDC3471755DF80C6A | T13: 44658.385 | U13: 2022-04-07
A14: exchange | B14: Binance | C14: 용범 | D14: Main | E14: 2 | F14: XRP | G14: #N/A | I14: binance | J14: 용범 | K14: XRP | L14: XRP | M14: 2000.5 | N14: raQwCVAJVqjrVm1Nj5SFRcX8i22BhdC9WA | O14: 2928323236 | P14: exchange | Q14: Upbit | R14: 용범 | S14: FCB169447A1AB867DF7B4037B933712C74EA1801DA2DC20ECAB8A3D7322B9677 | T14: 44650.717 | U14: 2022-03-30
A15: exchange | B15: FTX | C15: BBRICK | D15: B-Brick | E15: 8 | F15: ETH | G15: 0xBA7600fa3507c8f357C6206B645385D7e4723895 | I15: FTX | J15: BBRICK | K15: ETH | L15: ETH | M15: 500 | N15: 0x5d6fcf22aa4e4ff8da0abe329392e7c5306d22f3 | O15: 2928323236 | S15: 0x9d4a55758a5e08d32d9183ef3efd73796158b2381758b07590c9e60745d2cdb0 | T15: 44616.55 | U15: 2022-02-24
A16: exchange | B16: Binance | C16: 용범 | D16: Main | E16: 2 | F16: XRP | G16: #N/A | I16: binance | J16: 용범 | K16: XRP | L16: XRP | M16: 125.15 | N16: raQwCVAJVqjrVm1Nj5SFRcX8i22BhdC9WA | O16: 2928323236 | P16: exchange | Q16: Upbit | R16: 용범 | S16: FBA64372A02B89D79635A30ED10691E51B70806508C03EE2A380C19FA2C368A3 | T16: 44650.647 | U16: 2022-03-30
A17: exchange | B17: Binance | C17: BBRICK | D17: Main | E17: 10012 | F17: XLM | G17: GAHK7EEG2WWHVKDNT4CEQFZGKF2LGDSW2IVM4S5DP42RBW3K6BTODB4A | H17: 1061941801 | I17: Binance | J17: BBRICK | K17: XLM | L17: XLM | M17: 199295 | N17: GAJWYT5AIFS6LRUIDXGII4THBSW6DI3WLTULCDK63QN43L7DTSNENUNS | O17: bc6bdca3b4b911ec | P17: exchange | Q17: GDAC | R17: Peertec | S17: 33cd8cbf9172d2ceca291d0d9522369887edf18768d8311357d587834a1e66de | T17: 44695.391 | U17: 2022-05-14
A18: exchange | B18: FTX | C18: BBRICK | D18: B-Brick | E18: 8 | F18: SOL | G18: 4WALSVwxUyuXkxFqSwcweEgh2ddYjYoaFw3yUw3GMDPK | I18: FTX | J18: BBRICK | K18: SOL | M18: 1496.579 | T18: 44579.468 | U18: 2022-01-18
A19: exchange | B19: FTX | C19: BBRICK | D19: B-Brick | E19: 8 | F19: SOL | G19: 4WALSVwxUyuXkxFqSwcweEgh2ddYjYoaFw3yUw3GMDPK | I19: FTX | J19: BBRICK | K19: SOL | L19: SOL | M19: 1 | N19: SUZXwKfyPi8U4nMJNvT6b7WgDkaKmHvfVT9uE3yZYjx | P19: exchange | Q19: Binance | R19: BBRICK | S19: 3ptXchY1pEJAFuAQmo7uc4CkHd36Zf1xbnUM4E2FX6QNsSmFn1rwAWgtiQESRvsvnPgnnoy12KXtj9W63b7uZMz | T19: 44579.449 | U19: 2022-01-18
A20: exchange | B20: FTX | C20: BBRICK | D20: B-Brick | E20: 8 | F20: SOL | G20: 4WALSVwxUyuXkxFqSwcweEgh2ddYjYoaFw3yUw3GMDPK | I20: FTX | J20: BBRICK | K20: SOL | M20: 1497.579 | T20: 44578.655 | U20: 2022-01-17
A21: exchange | B21: FTX | C21: BBRICK | D21: B-Brick | E21: 8 | F21: SOL | G21: 4WALSVwxUyuXkxFqSwcweEgh2ddYjYoaFw3yUw3GMDPK | I21: FTX | J21: BBRICK | K21: SOL | M21: 1497.579 | T21: 44564.571 | U21: 2022-01-03
A22: exchange | B22: Binance | C22: BBRICK | D22: Main | E22: 10012 | F22: USDT | I22: Binance | J22: BBRICK | K22: USDT | L22: BSC | M22: 929.96019 | N22: 0x8dbe9c44a42050da44f075149c1ff49b18bcaf3f | P22: exchange | Q22: Binance | R22: 용범 | S22: Internal transfer 106502665267 | T22: 44694.993 | U22: 2022-05-13
A23: exchange | B23: Binance | C23: BBRICK | D23: Main | E23: 10012 | F23: USDT | I23: Binance | J23: BBRICK | K23: USDT | L23: BSC | M23: 425560.42 | N23: 0x8dbe9c44a42050da44f075149c1ff49b18bcaf3f | P23: exchange | Q23: Binance | R23: 용범 | S23: Internal transfer 106485937900 | T23: 44694.9 | U23: 2022-05-13
A24: exchange | B24: FTX | C24: BBRICK | D24: B-Brick | E24: 8 | F24: USDC | G24: 0xAa149A5172c5f27a8a259001AD3d62B2166Ae851 | I24: FTX | J24: BBRICK | K24: USDC | M24: 1222198 | T24: 44579.468 | U24: 2022-01-18
A25: exchange | B25: Binance | C25: BBRICK | D25: Main | E25: 10012 | F25: BNB | I25: Binance | J25: BBRICK | K25: BNB | L25: BSC | M25: 19.316237 | N25: 0x8dbe9c44a42050da44f075149c1ff49b18bcaf3f | P25: exchange | Q25: Binance | R25: 용범 | S25: Internal transfer 106450526173 | T25: 44694.661 | U25: 2022-05-13
A26: exchange | B26: FTX | C26: BBRICK | D26: B-Brick | E26: 8 | F26: USDC | G26: 0xAa149A5172c5f27a8a259001AD3d62B2166Ae851 | I26: FTX | J26: BBRICK | K26: USDC | M26: 1512134 | T26: 44578.655 | U26: 2022-01-17
A27: Wallet | B27: Terra | C27: BBRICK | D27: 비브릭용_Terra_wallet | G27: terra174evzq0tnd0uvzkkrvg08n9geqpcsvdrychcm8 | I27: 비브릭 테라 | J27: BBRICK | K27: UST | L27: Terra | M27: 8838617 | N27: terra1luagdjcr9c9yvp3ak4d7chjm5gldcmgln5rku5 | O27: 2482774378 | P27: exchange | Q27: FTX | R27: 권용진 | S27: AD1CABD4855104EE090261477D20292F9CDA81C1E5C1B6B8829657E9BDBB6B8E | T27: 44693.503 | U27: 2022-05-12
A28: Wallet | B28: Terra | C28: BBRICK | D28: 비브릭용_Terra_wallet | G28: terra174evzq0tnd0uvzkkrvg08n9geqpcsvdrychcm8 | I28: 비브릭 테라 | J28: BBRICK | K28: UST | L28: Terra | M28: 9000000 | N28: terra1luagdjcr9c9yvp3ak4d7chjm5gldcmgln5rku5 | O28: 2482774378 | P28: exchange | Q28: FTX | R28: 권용진 | S28: D98B889BD99CD46A9C9B058F3A3077653B70D172C577CCC9156C65FE868C583D | T28: 44693.471 | U28: 2022-05-12
A29: Wallet | B29: Terra | C29: BBRICK | D29: 비브릭용_Terra_wallet | G29: terra174evzq0tnd0uvzkkrvg08n9geqpcsvdrychcm8 | I29: 비브릭 테라 | J29: BBRICK | K29: UST | L29: Terra | M29: 1000000 | N29: terra1luagdjcr9c9yvp3ak4d7chjm5gldcmgln5rku5 | O29: 2482774378 | P29: exchange | Q29: FTX | R29: 권용진 | S29: 341CACAA713093B1F3A32894CD65AC2438DA06188085AD21F737E7FE9BA3358D | T29: 44693.463 | U29: 2022-05-12
A30: exchange | B30: OKEX | C30: Peertec | F30: KLAY | G30: 0x5006bc0d4fa0117e93d21aa663969fc6703a4319 | H30: 183316 | I30: OKEX | J30: Peertec | K30: KLAY | L30: KLAY | M30: 438237.26 | N30: 0x81251D5047F57Bb6158D39B72aE1bf92FaF26261 | P30: Wallet | Q30: Metamask | R30: Peertec | S30: 0x0d94918a52eaa0e0245590ed1e97451502fdce51700d7e62e9ba5bdf064b7f88 | T30: 44693.455 | U30: 2022-05-12
A31: exchange | B31: OKEX | C31: Peertec | F31: ETH | I31: OKEX | J31: Peertec | K31: ETH | L31: ETH | M31: 66.467999 | N31: 0x65f50dbae9d1d1f494df5c412a2b2841cf8e0a07 | P31: exchange | Q31: GDAC | R31: Peertec | S31: 0xa2746764eb1ca642262acb7f92963a67a9df3236b9935fad2108efaa2c3be53f | T31: 44693.418 | U31: 2022-05-12
A32: exchange | B32: Binance | C32: BBRICK | D32: Main | E32: 10012 | F32: BTC | G32: 19SK9LWSXLdmwPxvjPgvUrdaPhaPS6LaNu | I32: Binance | J32: BBRICK | K32: BTC | L32: BSC | M32: 64.216287 | N32: 0x8dbe9c44a42050da44f075149c1ff49b18bcaf3f | P32: exchange | Q32: Binance | R32: 용범 | S32: Internal transfer 106450334657 | T32: 44694.66 | U32: 2022-05-13
A33: exchange | B33: FTX | C33: BBRICK | D33: B-Brick | E33: 8 | F33: USDC | G33: 0xAa149A5172c5f27a8a259001AD3d62B2166Ae851 | I33: FTX | J33: BBRICK | K33: USDC | M33: 1463218 | T33: 44564.571 | U33: 2022-01-03
A34: exchange | B34: OKEX | C34: Peertec | F34: ETH | I34: OKEX | J34: Peertec | K34: ETH | L34: ETH | M34: 40.663 | N34: 0x65f50dbae9d1d1f494df5c412a2b2841cf8e0a07 | P34: exchange | Q34: GDAC | R34: Peertec | S34: 0xe0add4b1a828fa83aae85a62ce7027968aca5dcd8b92dc83d287b06f8e7343fc | T34: 44692.489 | U34: 2022-05-11
A35: Wallet | B35: Terra | C35: BBRICK | D35: 비브릭용_Terra_wallet | G35: terra174evzq0tnd0uvzkkrvg08n9geqpcsvdrychcm8 | I35: 비브릭 테라 | J35: BBRICK | K35: UST | L35: Terra | M35: 8000000 | N35: terra1luagdjcr9c9yvp3ak4d7chjm5gldcmgln5rku5 | O35: 1273090217 | P35: exchange | Q35: FTX | R35: BBRICK | S35: 8EA245015E46B6F751C0411C1B3AB6A77F7E3F35325A99C929333D041533DADC | T35: 44692.452 | U35: 2022-05-11
A36: Wallet | B36: Terra | C36: BBRICK | D36: 비브릭용_Terra_wallet | G36: terra174evzq0tnd0uvzkkrvg08n9geqpcsvdrychcm8 | I36: 비브릭 테라 | J36: BBRICK | K36: UST | L36: Terra | M36: 1137480 | N36: terra1s7gxam60m650w29s64ckqrw902c9nshgeu3zm8 | P36: Wallet | Q36: Terra | R36: 권용진 | S36: 4E74D03628C0EB809E4D9B8AEBB958BECE89C60532EBD99C2E3C97F485FE4B8E | T36: 44691.744 | U36: 2022-05-10
A37: Wallet | B37: Terra | C37: BBRICK | D37: 지닥용_Terra_wallet | G37: terra1j4u9e5n8xu9c9jykny8uqw6lde6843qczzwd0x | I37: 지닥용 테라 지갑 | J37: BBRICK | K37: UST | L37: Terra | M37: 93800 | N37: terra1luagdjcr9c9yvp3ak4d7chjm5gldcmgln5rku5 | O37: 823031602 | P37: exchange | Q37: FTX | R37: Peertec | S37: BFBB17729562505EF538A8D72DFE6B5DC638AB69A7C8A49EE068B7FFF79E2305 | T37: 44691.677 | U37: 2022-05-10
A38: exchange | B38: FTX | C38: BBRICK | D38: B-Brick | E38: 8 | F38: USDC | G38: 0xAa149A5172c5f27a8a259001AD3d62B2166Ae851 | I38: FTX | J38: BBRICK | K38: USDC | M38: 214064.3 | T38: 44178.764 | U38: 2020-12-13
A39: Wallet | B39: Terra | C39: BBRICK | D39: 비브릭용_Terra_wallet | G39: terra174evzq0tnd0uvzkkrvg08n9geqpcsvdrychcm8 | I39: 비브릭 테라 | J39: BBRICK | K39: UST | L39: Terra | M39: 5000000 | N39: terra1luagdjcr9c9yvp3ak4d7chjm5gldcmgln5rku5 | O39: 1273090217 | P39: exchange | Q39: FTX | R39: BBRICK | S39: 23EED29AA4B6DACB66F3E4AEB58F995A0DD7D03EA3D71215BF19C47A11BE7F16 | T39: 44691.52 | U39: 2022-05-10
A40: exchange | B40: Binance | C40: BBRICK | D40: Main | E40: 10012 | F40: BTC | G40: 19SK9LWSXLdmwPxvjPgvUrdaPhaPS6LaNu | I40: Binance | J40: BBRICK | K40: BTC | L40: BTC | M40: 42.736454 | N40: 38DHELMPRpYKZ2WBsbSSu2XpL1z6DCuxbA | P40: exchange | Q40: GDAC | R40: Peertec | S40: a4ce5db4b55eae3f9b8d2de9268cc04b4456a08a1f05e3b865bce0c7b2b48370 | T40: 44694.531 | U40: 2022-05-13
...

Sheet (참고) Index
A1: idx | B1: account type | C1: name | D1: ownership | E1: subname | F1: 출금 최초시간 | G1: 입금 최초시간
A2: 1 | B2: exchange | C2: FTX | D2: Peertec | E2: Main_Peertec | F2: 44636.471 | G2: 44351.514
A3: 2 | B3: exchange | C3: FTX | D3: BBRICK | E3: Main_Bbrick | F3: 44340.675 | G3: 44340.637
A4: 3 | B4: exchange | C4: FTX | D4: BBRICK | E4: Bithumb_ETH | F4: 44089.663 | G4: 44082.68
A5: 4 | B5: exchange | C5: FTX | D5: BBRICK | E5: B-Brick | F5: 44477.632 | G5: 44168.476
A6: 5 | B6: exchange | C6: FTX | D6: BBRICK | E6: Coinone | F6: 44250.765 | G6: 44306.2
A7: 6 | B7: exchange | C7: FTX | D7: BBRICK | E7: Bithumb | F7: 44392.783 | G7: 44041.567
A8: 7 | B8: exchange | C8: FTX | D8: BBRICK | E8: BTSE | F8: 44068.638 | G8: 44043.458
A9: 8 | B9: exchange | C9: Binance | D9: BBRICK | E9: Main | F9: 44265.431 | G9: 44265.468
A10: 9 | B10: exchange | C10: Binance | D10: BBRICK | E10: Sub | G10: 44566.66
A11: 10 | B11: exchange | C11: GDAC | D11: Peertec | E11: Gdac_index
A12: 11 | B12: exchange | C12: GDAC | D12: Peertec | E12: 거래소지갑
A13: 12 | B13: exchange | C13: Binance | D13: 용범 | E13: Main | F13: 44650.658 | G13: 44650.647
A14: 13 | B14: Wallet | C14: Metamask | D14: BBRICK
A15: 14 | B15: Wallet | C15: Terra | D15: BBRICK | E15: 비브릭용_Terra_Wallet | F15: 44496.451 | G15: 44478.494
A16: 15 | B16: Wallet | C16: Terra | D16: BBRICK | E16: 지닥용_Terra_Wallet | F16: 44635.532 | G16: 44623.462
A17: 16 | B17: Wallet | C17: Atom | D17: BBRICK
A18: 17 | B18: Wallet | C18: Klaytn | D18: BBRICK | E18: 지닥용 메타마스크 지갑
A19: 18 | B19: Wallet | C19: Tron | D19: BBRICK
A20: 19 | B20: Wallet | C20: Metamask | D20: Peertec
A21: 20 | B21: exchange | C21: 비둘기지갑 | D21: BBRICK | E21: 차이
A22: 21 | B22: exchange | C22: 비둘기지갑 | D22: BBRICK | E22: Trade wallet
A23: 22 | B23: exchange | C23: 비둘기지갑 | D23: BBRICK | E23: 비둘기 집금 지갑으로 추정
A24: 23 | B24: exchange | C24: 비둘기지갑 | D24: BBRICK | E24: Trade wallet_글로벌
A25: 24 | B25: Wallet | C25: Klaytn | D25: WTF | E25: what the frog owner address
A26: 25 | B26: Wallet | C26: Klaytn | D26: WTF | E26: wtfrog 발행 지갑
A27: 26 | B27: Wallet | C27: Klaytn | D27: WTF | E27: What The Frog Contract
A28: 27 | B28: exchange | C28: Binance | D28: Binance | E28: 거래소지갑
A29: 28 | B29: exchange | C29: Huobi | D29: Peertec | F29: 44237.732 | G29: 44232.773
A30: 29 | B30: exchange | C30: Huobi | D30: BBRICK | F30: 44695.68 | G30: 44695.712
A31: 30 | B31: Wallet | C31: Metamask | D31: BBRICK | E31: 차이 OTC 거래 지갑_BSC
A32: 31 | B32: Wallet | C32: Metamask | D32: Chai | E32: 차이 법인 지갑
A33: 32 | B33: Wallet | C33: Aurora | D33: 태호 | E33: 태호 관리 지갑? 확인 필요
A34: 33 | B34: exchange | C34: Bithumb | D34: 태호 | E34: 태호_개인_계정_지갑
A35: 34 | B35: exchange | C35: OKEX | D35: Peertec | F35: 44646.426 | G35: 44646.193
A36: 35 | B36: exchange | C36: OKEX | D36: BBRICK
A37: 36 | B37: exchange | C37: FTX | D37: 권용진 | E37: 개인_FTX_주소
A38: 37 | B38: exchange | C38: FTX | D38: BBRICK | E38: Chai | F38: 44693.977 | G38: 44693.916
A39: 38 | B39: exchange | C39: Upbit | D39: 용범 | E39: 레이너_전략_사용 | F39: 44496.606 | G39: 44488.768
A40: 39 | B40: exchange | C40: Binance | D40: 태호 | E40: 태호_개인 | F40: 44663.3 | G40: 44638
...
